Workbook

Sheet Distruibuição de aporte
A1: Aporte total | B1: =H15 -> 12000 | C1: =B1+G13 -> 255783.45
A2: Tipo de ativo | B2: Porcentagem desejada | C2: Proporção ajustada | D2: Diferença | E2: Condição | F2: % Atual | G2: Valor atual | H2: Aporte por ativo | I2: Valor após aportes
A3: Reserva de investimento | B3: 0.05 | C3: =IF(E3=1,D3/D13,0) -> 0.096234904 | D3: =IF(E3=1,C1*B3-G3,0) -> 12789.163 | E3: =IF(B3>G3/C1,1,0) -> 1 | F3: =G3/G13 -> 4.1020011e-08 | G3: ='RI, RV e RF'!F42 -> 0.01 | H3: =IF(G3/C1>B3,C1*B3-G3,C3*B1) -> 1154.8188 | I3: =G3+H3 -> 1154.8288 | J3: =I3/C1 -> 0.0045148692
A4: Reserva de valor | B4: 0.05 | C4: =IF(E4=1,D4/D13,0) -> 0.081239727 | D4: =IF(E4=1,C1*B4-G4,0) -> 10796.375 | E4: =IF(B4>G4/C1,1,0) -> 1 | F4: =G4/G13 -> 0.0081744593 | G4: ='RI, RV e RF'!F43 -> 1992.7979 | H4: =IF(H3>0,C4*B1,C4*(B1-H3)) -> 974.87673 | I4: =G4+H4 -> 2967.6747 | J4: =I4/C1 -> 0.011602293
A5: Renda fixa BR | B5: 0.1 | C5: =IF(E5=1,D5/D13,0) -> 0.095408334 | D5: =IF(E5=1,C1*B5-G5,0) -> 12679.315 | E5: =IF(B5>G5/C1,1,0) -> 1 | F5: =G5/G13 -> 0.052911835 | G5: ='RI, RV e RF'!F44 -> 12899.03 | H5: =IF(H3>0,C5*B1,C5*(B1-H3)) -> 1144.9 | I5: =G5+H5 -> 14043.93 | J5: =I5/C1 -> 0.054905545
A6: FIIs | B6: 0.15 | C6: =IF(E6=1,D6/D13,0) -> 0 | D6: =IF(E6=1,C1*B6-G6,0) -> 0 | E6: =IF(B6>G6/C1,1,0) -> 0 | F6: =G6/G13 -> 0.6532961 | G6: =FII!F23 -> 159262.78 | H6: =IF(H3>0,C6*B1,C6*(B1-H3)) -> 0 | I6: =G6+H6 -> 159262.78 | J6: =I6/C1 -> 0.62264692
A7: Ações BR | B7: 0.35 | C7: =IF(E7=1,D7/D13,0) -> 0.36904235 | D7: =IF(E7=1,C1*B7-G7,0) -> 49043.979 | E7: =IF(B7>G7/C1,1,0) -> 1 | F7: =G7/G13 -> 0.16604995 | G7: ='Ações'!E102 -> 40480.23 | H7: =IF(H3>0,C7*B1,C7*(B1-H3)) -> 4428.5082 | I7: =G7+H7 -> 44908.738 | J7: =I7/C1 -> 0.17557327
A8: Ações US | B8: 0.1 | C8: =IF(E8=1,D8/D13,0) -> 0.12050918 | D8: =IF(E8=1,C1*B8-G8,0) -> 16015.099 | E8: =IF(B8>G8/C1,1,0) -> 1 | F8: =G8/G13 -> 0.039228449 | G8: =Exterior!H42 -> 9563.2469 | H8: =IF(H3>0,C8*B1,C8*(B1-H3)) -> 1446.1101 | I8: =G8+H8 -> 11009.357 | J8: =I8/C1 -> 0.043041709
A9: REITs | B9: 0.05 | C9: =IF(E9=1,D9/D13,0) -> 0.061962672 | D9: =IF(E9=1,C1*B9-G9,0) -> 8234.5455 | E9: =IF(B9>G9/C1,1,0) -> 1 | F9: =G9/G13 -> 0.018683086 | G9: =Exterior!H43 -> 4554.6272 | H9: =IF(H3>0,C9*B1,C9*(B1-H3)) -> 743.55207 | I9: =G9+H9 -> 5298.1793 | J9: =I9/C1 -> 0.020713534
A10: Renda fixa no exterior | B10: 0.05 | C10: =IF(E10=1,D10/D13,0) -> 0.058949277 | D10: =IF(E10=1,C1*B10-G10,0) -> 7834.0795 | E10: =IF(B10>G10/C1,1,0) -> 1 | F10: =G10/G13 -> 0.020325798 | G10: =Exterior!H44 -> 4955.0932 | H10: =IF(H3>0,C10*B1,C10*(B1-H3)) -> 707.39132 | I10: =G10+H10 -> 5662.4845 | J10: =I10/C1 -> 0.022137806
A11: Ações Europa | B11: 0.05 | C11: =IF(E11=1,D11/D13,0) -> 0.059711567 | D11: =IF(E11=1,C1*B11-G11,0) -> 7935.3844 | E11: =IF(B11>G11/C1,1,0) -> 1 | F11: =G11/G13 -> 0.019910245 | G11: =Exterior!H45 -> 4853.7884 | H11: =IF(H3>0,C11*B1,C11*(B1-H3)) -> 716.53881 | I11: =G11+H11 -> 5570.3272 | J11: =I11/C1 -> 0.021777512
A12: Ações Asia | B12: 0.05 | C12: =IF(E12=1,D12/D13,0) -> 0.056941996 | D12: =IF(E12=1,C1*B12-G12,0) -> 7567.3215 | E12: =IF(B12>G12/C1,1,0) -> 1 | F12: =G12/G13 -> 0.02142004 | G12: =Exterior!H46 -> 5221.8513 | H12: =IF(H3>0,C12*B1,C12*(B1-H3)) -> 683.30395 | I12: =G12+H12 -> 5905.1552 | J12: =I12/C1 -> 0.023086541
A13: Soma: | B13: =SUM(B3:B12) -> 1 | C13: =SUM(C3:C12) -> 1 | D13: =SUM(D3:D12) -> 132895.26 | F13: =SUM(F3:F12) -> 1 | G13: =SUM(G3:G12) -> 243783.45 | H13: =SUM(H3:H12) -> 12000 | I13: =SUM(I3:I12) -> 255783.45 | J13: =SUM(J3:J12) -> 1
A15: Aporte | B15: 12000 | F15: =G13+B15 -> 255783.45 | H15: =SUM(H16,B15) -> 12000 | J15: =J16/2 -> 159696.61
B16: 12084.15 | F16: =B16-B17 -> 0 | G16: =I16*B16 -> 63609.757 | H16: =IF(G16/F15<1,0,J15-F15) -> 0 | I16: =IFERROR(__xludf.DUMMYFUNCTION("GOOGLEFINANCE(""CURRENCY:USDBRL"")"),5.2639) -> 5.2639 | J16: =SUM(G16,G13,B15) -> 319393.21
B17: =(G16-H16)/I16 -> 12084.15 | G17: =I16*B17 -> 63609.757

Sheet RI, RV e RF
B1: Ativo | C1: Setor | D1: Quantidade | E1: Cotação | F1: Saldo | G1: %Carteira | H1: %C/aporte | I1: % Ideal | J1: Bal | K1: Bal | M1: Aporte: | N1: =SUM(D42:D46) -> 3274.5956 | O1: Aporte ideal por ativo | P1: % após aport
A2: 1 | B2: ROMP | D2: 0.01 | E2: 1 | F2: =D2*E2 -> 0.01 | G2: =IFS(L2="Grupo 0",0,L2="Grupo 1",F2/F42,L2="Grupo 2",F2/F43,L2="Grupo 3",F2/F44,L2="Grupo 4",F2/F45,L2="Grupo 5",F2/F46) -> 1 | H2: =IFS(L2="Grupo 0",0,L2="Grupo 1",F2/E42,L2="Grupo 2",F2/E43,L2="Grupo 3",F2/E44,L2="Grupo 4",F2/E45,L2="Grupo 5",F2/E46) -> 8.6592918e-06 | I2: =IFS(L2="Grupo 0",0,L2="Grupo 1",M2/M42,L2="Grupo 2",M2/M43,L2="Grupo 3",M2/M44,L2="Grupo 4",M2/M45,L2="Grupo 5",M2/M46) -> 1 | J2: =IFS(L2="Grupo 0",0,L2="Grupo 1",K2/K42,L2="Grupo 2",K2/K43,L2="Grupo 3",K2/K44,L2="Grupo 4",K2/K45,L2="Grupo 5",K2/K46) -> 1 | K2: =IFS(L2="Grupo 0",0,L2="Grupo 1",(E42*I2-F2)*N2,L2="Grupo 2",(E43*I2-F2)*N2,L2="Grupo 3",(E44*I2-F2)*N2,L2="Grupo 4",(E45*I2-F2)*N2,L2="Grupo 5",(E46*I2-F2)*N2) -> 1154.8188 | L2: Grupo 1 | M2: 5 | N2: =IF(I2<H2,0,1) -> 1 | O2: =IFS(L2="Grupo 0",0,L2="Grupo 1",J2*D42,L2="Grupo 2",J2*D43,L2="Grupo 3",J2*D44,L2="Grupo 4",J2*D45,L2="Grupo 5",J2*D46) -> 1154.8188 | P2: =(F2+O2)/D41 -> 0.063569376
A3: 2 | F3: =D3*E3 -> 0 | G3: =IFS(L3="Grupo 0",0,L3="Grupo 1",F3/F42,L3="Grupo 2",F3/F43,L3="Grupo 3",F3/F44,L3="Grupo 4",F3/F45,L3="Grupo 5",F3/F46) -> 0 | H3: =IFS(L3="Grupo 0",0,L3="Grupo 1",F3/E42,L3="Grupo 2",F3/E43,L3="Grupo 3",F3/E44,L3="Grupo 4",F3/E45,L3="Grupo 5",F3/E46) -> 0 | I3: =IFS(L3="Grupo 0",0,L3="Grupo 1",M3/M42,L3="Grupo 2",M3/M43,L3="Grupo 3",M3/M44,L3="Grupo 4",M3/M45,L3="Grupo 5",M3/M46) -> 0 | J3: =IFS(L3="Grupo 0",0,L3="Grupo 1",K3/K42,L3="Grupo 2",K3/K43,L3="Grupo 3",K3/K44,L3="Grupo 4",K3/K45,L3="Grupo 5",K3/K46) -> 0 | K3: =IFS(L3="Grupo 0",0,L3="Grupo 1",(E42*I3-F3)*N3,L3="Grupo 2",(E43*I3-F3)*N3,L3="Grupo 3",(E44*I3-F3)*N3,L3="Grupo 4",(E45*I3-F3)*N3,L3="Grupo 5",(E46*I3-F3)*N3) -> 0 | L3: Grupo 0 | M3: 1 | N3: =IF(I3<H3,0,1) -> 1 | O3: =IFS(L3="Grupo 0",0,L3="Grupo 1",J3*D42,L3="Grupo 2",J3*D43,L3="Grupo 3",J3*D44,L3="Grupo 4",J3*D45,L3="Grupo 5",J3*D46) -> 0 | P3: =(F3+O3)/D41 -> 0
A4: 3 | F4: =D4*E4 -> 0 | G4: =IFS(L4="Grupo 0",0,L4="Grupo 1",F4/F42,L4="Grupo 2",F4/F43,L4="Grupo 3",F4/F44,L4="Grupo 4",F4/F45,L4="Grupo 5",F4/F46) -> 0 | H4: =IFS(L4="Grupo 0",0,L4="Grupo 1",F4/E42,L4="Grupo 2",F4/E43,L4="Grupo 3",F4/E44,L4="Grupo 4",F4/E45,L4="Grupo 5",F4/E46) -> 0 | I4: =IFS(L4="Grupo 0",0,L4="Grupo 1",M4/M42,L4="Grupo 2",M4/M43,L4="Grupo 3",M4/M44,L4="Grupo 4",M4/M45,L4="Grupo 5",M4/M46) -> 0 | J4: =IFS(L4="Grupo 0",0,L4="Grupo 1",K4/K42,L4="Grupo 2",K4/K43,L4="Grupo 3",K4/K44,L4="Grupo 4",K4/K45,L4="Grupo 5",K4/K46) -> 0 | K4: =IFS(L4="Grupo 0",0,L4="Grupo 1",(E42*I4-F4)*N4,L4="Grupo 2",(E43*I4-F4)*N4,L4="Grupo 3",(E44*I4-F4)*N4,L4="Grupo 4",(E45*I4-F4)*N4,L4="Grupo 5",(E46*I4-F4)*N4) -> 0 | L4: Grupo 0 | M4: 10 | N4: =IF(I4<H4,0,1) -> 1 | O4: =IFS(L4="Grupo 0",0,L4="Grupo 1",J4*D42,L4="Grupo 2",J4*D43,L4="Grupo 3",J4*D44,L4="Grupo 4",J4*D45,L4="Grupo 5",J4*D46) -> 0 | P4: =(F4+O4)/D41 -> 0
A5: 4 | F5: =D5*E5 -> 0 | G5: =IFS(L5="Grupo 0",0,L5="Grupo 1",F5/F42,L5="Grupo 2",F5/F43,L5="Grupo 3",F5/F44,L5="Grupo 4",F5/F45,L5="Grupo 5",F5/F46) -> 0 | H5: =IFS(L5="Grupo 0",0,L5="Grupo 1",F5/E42,L5="Grupo 2",F5/E43,L5="Grupo 3",F5/E44,L5="Grupo 4",F5/E45,L5="Grupo 5",F5/E46) -> 0 | I5: =IFS(L5="Grupo 0",0,L5="Grupo 1",M5/M42,L5="Grupo 2",M5/M43,L5="Grupo 3",M5/M44,L5="Grupo 4",M5/M45,L5="Grupo 5",M5/M46) -> 0 | J5: =IFS(L5="Grupo 0",0,L5="Grupo 1",K5/K42,L5="Grupo 2",K5/K43,L5="Grupo 3",K5/K44,L5="Grupo 4",K5/K45,L5="Grupo 5",K5/K46) -> 0 | K5: =IFS(L5="Grupo 0",0,L5="Grupo 1",(E42*I5-F5)*N5,L5="Grupo 2",(E43*I5-F5)*N5,L5="Grupo 3",(E44*I5-F5)*N5,L5="Grupo 4",(E45*I5-F5)*N5,L5="Grupo 5",(E46*I5-F5)*N5) -> 0 | L5: Grupo 0 | M5: 1 | N5: =IF(I5<H5,0,1) -> 1 | O5: =IFS(L5="Grupo 0",0,L5="Grupo 1",J5*D42,L5="Grupo 2",J5*D43,L5="Grupo 3",J5*D44,L5="Grupo 4",J5*D45,L5="Grupo 5",J5*D46) -> 0 | P5: =(F5+O5)/D41 -> 0
A6: 5 | B6: Tesouro IPCA | D6: 3102.81 | E6: 1 | F6: =D6*E6 -> 3102.81 | G6: =IFS(L6="Grupo 0",0,L6="Grupo 1",F6/F42,L6="Grupo 2",F6/F43,L6="Grupo 3",F6/F44,L6="Grupo 4",F6/F45,L6="Grupo 5",F6/F46) -> 0.24054599 | H6: =IFS(L6="Grupo 0",0,L6="Grupo 1",F6/E42,L6="Grupo 2",F6/E43,L6="Grupo 3",F6/E44,L6="Grupo 4",F6/E45,L6="Grupo 5",F6/E46) -> 0.22093602 | I6: =IFS(L6="Grupo 0",0,L6="Grupo 1",M6/M42,L6="Grupo 2",M6/M43,L6="Grupo 3",M6/M44,L6="Grupo 4",M6/M45,L6="Grupo 5",M6/M46) -> 0.5 | J6: =IFS(L6="Grupo 0",0,L6="Grupo 1",K6/K42,L6="Grupo 2",K6/K43,L6="Grupo 3",K6/K44,L6="Grupo 4",K6/K45,L6="Grupo 5",K6/K46) -> 1 | K6: =IFS(L6="Grupo 0",0,L6="Grupo 1",(E42*I6-F6)*N6,L6="Grupo 2",(E43*I6-F6)*N6,L6="Grupo 3",(E44*I6-F6)*N6,L6="Grupo 4",(E45*I6-F6)*N6,L6="Grupo 5",(E46*I6-F6)*N6) -> 3919.155 | L6: Grupo 3 | M6: 10 | N6: =IF(I6<H6,0,1) -> 1 | O6: =IFS(L6="Grupo 0",0,L6="Grupo 1",J6*D42,L6="Grupo 2",J6*D43,L6="Grupo 3",J6*D44,L6="Grupo 4",J6*D45,L6="Grupo 5",J6*D46) -> 1144.9 | P6: =(F6+O6)/D41 -> 0.2338219
A7: 6 | B7: CDB, LCA, ETC | D7: 9796.22 | E7: 1 | F7: =D7*E7 -> 9796.22 | G7: =IFS(L7="Grupo 0",0,L7="Grupo 1",F7/F42,L7="Grupo 2",F7/F43,L7="Grupo 3",F7/F44,L7="Grupo 4",F7/F45,L7="Grupo 5",F7/F46) -> 0.75945401 | H7: =IFS(L7="Grupo 0",0,L7="Grupo 1",F7/E42,L7="Grupo 2",F7/E43,L7="Grupo 3",F7/E44,L7="Grupo 4",F7/E45,L7="Grupo 5",F7/E46) -> 0.69754122 | I7: =IFS(L7="Grupo 0",0,L7="Grupo 1",M7/M42,L7="Grupo 2",M7/M43,L7="Grupo 3",M7/M44,L7="Grupo 4",M7/M45,L7="Grupo 5",M7/M46) -> 0.5 | J7: =IFS(L7="Grupo 0",0,L7="Grupo 1",K7/K42,L7="Grupo 2",K7/K43,L7="Grupo 3",K7/K44,L7="Grupo 4",K7/K45,L7="Grupo 5",K7/K46) -> 0 | K7: =IFS(L7="Grupo 0",0,L7="Grupo 1",(E42*I7-F7)*N7,L7="Grupo 2",(E43*I7-F7)*N7,L7="Grupo 3",(E44*I7-F7)*N7,L7="Grupo 4",(E45*I7-F7)*N7,L7="Grupo 5",(E46*I7-F7)*N7) -> 0 | L7: Grupo 3 | M7: 10 | N7: =IF(I7<H7,0,1) -> 0 | O7: =IFS(L7="Grupo 0",0,L7="Grupo 1",J7*D42,L7="Grupo 2",J7*D43,L7="Grupo 3",J7*D44,L7="Grupo 4",J7*D45,L7="Grupo 5",J7*D46) -> 0 | P7: =(F7+O7)/D41 -> 0.53924839
A8: 7 | F8: =D8*E8 -> 0 | G8: =IFS(L8="Grupo 0",0,L8="Grupo 1",F8/F42,L8="Grupo 2",F8/F43,L8="Grupo 3",F8/F44,L8="Grupo 4",F8/F45,L8="Grupo 5",F8/F46) -> 0 | H8: =IFS(L8="Grupo 0",0,L8="Grupo 1",F8/E42,L8="Grupo 2",F8/E43,L8="Grupo 3",F8/E44,L8="Grupo 4",F8/E45,L8="Grupo 5",F8/E46) -> 0 | I8: =IFS(L8="Grupo 0",0,L8="Grupo 1",M8/M42,L8="Grupo 2",M8/M43,L8="Grupo 3",M8/M44,L8="Grupo 4",M8/M45,L8="Grupo 5",M8/M46) -> 0 | J8: =IFS(L8="Grupo 0",0,L8="Grupo 1",K8/K42,L8="Grupo 2",K8/K43,L8="Grupo 3",K8/K44,L8="Grupo 4",K8/K45,L8="Grupo 5",K8/K46) -> 0 | K8: =IFS(L8="Grupo 0",0,L8="Grupo 1",(E42*I8-F8)*N8,L8="Grupo 2",(E43*I8-F8)*N8,L8="Grupo 3",(E44*I8-F8)*N8,L8="Grupo 4",(E45*I8-F8)*N8,L8="Grupo 5",(E46*I8-F8)*N8) -> 0 | L8: Grupo 0 | N8: =IF(I8<H8,0,1) -> 1 | O8: =IFS(L8="Grupo 0",0,L8="Grupo 1",J8*D42,L8="Grupo 2",J8*D43,L8="Grupo 3",J8*D44,L8="Grupo 4",J8*D45,L8="Grupo 5",J8*D46) -> 0 | P8: =(F8+O8)/D41 -> 0
A9: 8 | F9: =D9*E9 -> 0 | G9: =IFS(L9="Grupo 0",0,L9="Grupo 1",F9/F42,L9="Grupo 2",F9/F43,L9="Grupo 3",F9/F44,L9="Grupo 4",F9/F45,L9="Grupo 5",F9/F46) -> 0 | H9: =IFS(L9="Grupo 0",0,L9="Grupo 1",F9/E42,L9="Grupo 2",F9/E43,L9="Grupo 3",F9/E44,L9="Grupo 4",F9/E45,L9="Grupo 5",F9/E46) -> 0 | I9: =IFS(L9="Grupo 0",0,L9="Grupo 1",M9/M42,L9="Grupo 2",M9/M43,L9="Grupo 3",M9/M44,L9="Grupo 4",M9/M45,L9="Grupo 5",M9/M46) -> 0 | J9: =IFS(L9="Grupo 0",0,L9="Grupo 1",K9/K42,L9="Grupo 2",K9/K43,L9="Grupo 3",K9/K44,L9="Grupo 4",K9/K45,L9="Grupo 5",K9/K46) -> 0 | K9: =IFS(L9="Grupo 0",0,L9="Grupo 1",(E42*I9-F9)*N9,L9="Grupo 2",(E43*I9-F9)*N9,L9="Grupo 3",(E44*I9-F9)*N9,L9="Grupo 4",(E45*I9-F9)*N9,L9="Grupo 5",(E46*I9-F9)*N9) -> 0 | L9: Grupo 0 | N9: =IF(I9<H9,0,1) -> 1 | O9: =IFS(L9="Grupo 0",0,L9="Grupo 1",J9*D42,L9="Grupo 2",J9*D43,L9="Grupo 3",J9*D44,L9="Grupo 4",J9*D45,L9="Grupo 5",J9*D46) -> 0 | P9: =(F9+O9)/D41 -> 0
A10: 9 | F10: =D10*E10 -> 0 | G10: =IFS(L10="Grupo 0",0,L10="Grupo 1",F10/F42,L10="Grupo 2",F10/F43,L10="Grupo 3",F10/F44,L10="Grupo 4",F10/F45,L10="Grupo 5",F10/F46) -> 0 | H10: =IFS(L10="Grupo 0",0,L10="Grupo 1",F10/E42,L10="Grupo 2",F10/E43,L10="Grupo 3",F10/E44,L10="Grupo 4",F10/E45,L10="Grupo 5",F10/E46) -> 0 | I10: =IFS(L10="Grupo 0",0,L10="Grupo 1",M10/M42,L10="Grupo 2",M10/M43,L10="Grupo 3",M10/M44,L10="Grupo 4",M10/M45,L10="Grupo 5",M10/M46) -> 0 | J10: =IFS(L10="Grupo 0",0,L10="Grupo 1",K10/K42,L10="Grupo 2",K10/K43,L10="Grupo 3",K10/K44,L10="Grupo 4",K10/K45,L10="Grupo 5",K10/K46) -> 0 | K10: =IFS(L10="Grupo 0",0,L10="Grupo 1",(E42*I10-F10)*N10,L10="Grupo 2",(E43*I10-F10)*N10,L10="Grupo 3",(E44*I10-F10)*N10,L10="Grupo 4",(E45*I10-F10)*N10,L10="Grupo 5",(E46*I10-F10)*N10) -> 0 | L10: Grupo 0 | N10: =IF(I10<H10,0,1) -> 1 | O10: =IFS(L10="Grupo 0",0,L10="Grupo 1",J10*D42,L10="Grupo 2",J10*D43,L10="Grupo 3",J10*D44,L10="Grupo 4",J10*D45,L10="Grupo 5",J10*D46) -> 0 | P10: =(F10+O10)/D41 -> 0
A11: 10 | F11: =D11*E11 -> 0 | G11: =IFS(L11="Grupo 0",0,L11="Grupo 1",F11/F42,L11="Grupo 2",F11/F43,L11="Grupo 3",F11/F44,L11="Grupo 4",F11/F45,L11="Grupo 5",F11/F46) -> 0 | H11: =IFS(L11="Grupo 0",0,L11="Grupo 1",F11/E42,L11="Grupo 2",F11/E43,L11="Grupo 3",F11/E44,L11="Grupo 4",F11/E45,L11="Grupo 5",F11/E46) -> 0 | I11: =IFS(L11="Grupo 0",0,L11="Grupo 1",M11/M42,L11="Grupo 2",M11/M43,L11="Grupo 3",M11/M44,L11="Grupo 4",M11/M45,L11="Grupo 5",M11/M46) -> 0 | J11: =IFS(L11="Grupo 0",0,L11="Grupo 1",K11/K42,L11="Grupo 2",K11/K43,L11="Grupo 3",K11/K44,L11="Grupo 4",K11/K45,L11="Grupo 5",K11/K46) -> 0 | K11: =IFS(L11="Grupo 0",0,L11="Grupo 1",(E42*I11-F11)*N11,L11="Grupo 2",(E43*I11-F11)*N11,L11="Grupo 3",(E44*I10-F11)*N11,L11="Grupo 4",(E45*I11-F11)*N11,L11="Grupo 5",(E46*I11-F11)*N11) -> 0 | L11: Grupo 0 | N11: =IF(I11<H11,0,1) -> 1 | O11: =IFS(L11="Grupo 0",0,L11="Grupo 1",J11*D42,L11="Grupo 2",J11*D43,L11="Grupo 3",J11*D44,L11="Grupo 4",J11*D45,L11="Grupo 5",J11*D46) -> 0 | P11: =(F11+O11)/D41 -> 0
A12: 11 | F12: =D12*E12 -> 0 | G12: =IFS(L12="Grupo 0",0,L12="Grupo 1",F12/F42,L12="Grupo 2",F12/F43,L12="Grupo 3",F12/F44,L12="Grupo 4",F12/F45,L12="Grupo 5",F12/F46) -> 0 | H12: =IFS(L12="Grupo 0",0,L12="Grupo 1",F12/E42,L12="Grupo 2",F12/E43,L12="Grupo 3",F12/E44,L12="Grupo 4",F12/E45,L12="Grupo 5",F12/E46) -> 0 | I12: =IFS(L12="Grupo 0",0,L12="Grupo 1",M12/M42,L12="Grupo 2",M12/M43,L12="Grupo 3",M12/M44,L12="Grupo 4",M12/M45,L12="Grupo 5",M12/M46) -> 0 | J12: =IFS(L12="Grupo 0",0,L12="Grupo 1",K12/K42,L12="Grupo 2",K12/K43,L12="Grupo 3",K12/K44,L12="Grupo 4",K12/K45,L12="Grupo 5",K12/K46) -> 0 | K12: =IFS(L12="Grupo 0",0,L12="Grupo 1",(E42*I12-F12)*N12,L12="Grupo 2",(E43*I12-F12)*N12,L12="Grupo 3",(E44*I12-F12)*N12,L12="Grupo 4",(E45*I12-F12)*N12,L12="Grupo 5",(E46*I12-F12)*N12) -> 0 | L12: Grupo 0 | N12: =IF(I12<H12,0,1) -> 1 | O12: =IFS(L12="Grupo 0",0,L12="Grupo 1",J12*D42,L12="Grupo 2",J12*D43,L12="Grupo 3",J12*D44,L12="Grupo 4",J12*D45,L12="Grupo 5",J12*D46) -> 0 | P12: =(F12+O12)/D41 -> 0
A13: 12 | B13: BTC | C13: =IFERROR(__xludf.DUMMYFUNCTION("GOOGLEFINANCE(""CURRENCY:BTCUSD"")"),71027.81) -> 71027.81 | D13: 0.00533 | E13: =IFERROR(__xludf.DUMMYFUNCTION("GOOGLEFINANCE(""CURRENCY:BTCBRL"")"),373883.289) -> 373883.29 | F13: =D13*E13 -> 1992.7979 | G13: =IFS(L13="Grupo 0",0,L13="Grupo 1",F13/F42,L13="Grupo 2",F13/F43,L13="Grupo 3",F13/F44,L13="Grupo 4",F13/F45,L13="Grupo 5",F13/F46) -> 1 | H13: =IFS(L13="Grupo 0",0,L13="Grupo 1",F13/E42,L13="Grupo 2",F13/E43,L13="Grupo 3",F13/E44,L13="Grupo 4",F13/E45,L13="Grupo 5",F13/E46) -> 0.67150148 | I13: =IFS(L13="Grupo 0",0,L13="Grupo 1",M13/M42,L13="Grupo 2",M13/M43,L13="Grupo 3",M13/M44,L13="Grupo 4",M13/M45,L13="Grupo 5",M13/M46) -> 1 | J13: =IFS(L13="Grupo 0",0,L13="Grupo 1",K13/K42,L13="Grupo 2",K13/K43,L13="Grupo 3",K13/K44,L13="Grupo 4",K13/K45,L13="Grupo 5",K13/K46) -> 1 | K13: =IFS(L13="Grupo 0",0,L13="Grupo 1",(E42*I13-F13)*N13,L13="Grupo 2",(E43*I13-F13)*N13,L13="Grupo 3",(E44*I13-F13)*N13,L13="Grupo 4",(E45*I13-F13)*N13,L13="Grupo 5",(E46*I13-F13)*N13) -> 974.87673 | L13: Grupo 2 | M13: 10 | N13: =IF(I13<H13,0,1) -> 1 | O13: =IFS(L13="Grupo 0",0,L13="Grupo 1",J13*D42,L13="Grupo 2",J13*D43,L13="Grupo 3",J13*D44,L13="Grupo 4",J13*D45,L13="Grupo 5",J13*D46) -> 974.87673 | P13: =(F13+O13)/D41 -> 0.16336033
A14: 13 | F14: =D14*E14 -> 0 | G14: =IFS(L14="Grupo 0",0,L14="Grupo 1",F14/F42,L14="Grupo 2",F14/F43,L14="Grupo 3",F14/F44,L14="Grupo 4",F14/F45,L14="Grupo 5",F14/F46) -> 0 | H14: =IFS(L14="Grupo 0",0,L14="Grupo 1",F14/E42,L14="Grupo 2",F14/E43,L14="Grupo 3",F14/E44,L14="Grupo 4",F14/E45,L14="Grupo 5",F14/E46) -> 0 | I14: =IFS(L14="Grupo 0",0,L14="Grupo 1",M14/M42,L14="Grupo 2",M14/M43,L14="Grupo 3",M14/M44,L14="Grupo 4",M14/M45,L14="Grupo 5",M14/M46) -> 0 | J14: =IFS(L14="Grupo 0",0,L14="Grupo 1",K14/K42,L14="Grupo 2",K14/K43,L14="Grupo 3",K14/K44,L14="Grupo 4",K14/K45,L14="Grupo 5",K14/K46) -> 0 | K14: =IFS(L14="Grupo 0",0,L14="Grupo 1",(E42*I14-F14)*N14,L14="Grupo 2",(E43*I14-F14)*N14,L14="Grupo 3",(E44*I14-F14)*N14,L14="Grupo 4",(E45*I14-F14)*N14,L14="Grupo 5",(E46*I14-F14)*N14) -> 0 | L14: Grupo 0 | N14: =IF(I14<H14,0,1) -> 1 | O14: =IFS(L14="Grupo 0",0,L14="Grupo 1",J14*D42,L14="Grupo 2",J14*D43,L14="Grupo 3",J14*D44,L14="Grupo 4",J14*D45,L14="Grupo 5",J14*D46) -> 0 | P14: =(F14+O14)/D41 -> 0
A15: 14 | F15: =D15*E15 -> 0 | G15: =IFS(L15="Grupo 0",0,L15="Grupo 1",F15/F42,L15="Grupo 2",F15/F43,L15="Grupo 3",F15/F44,L15="Grupo 4",F15/F45,L15="Grupo 5",F15/F46) -> 0 | H15: =IFS(L15="Grupo 0",0,L15="Grupo 1",F15/E42,L15="Grupo 2",F15/E43,L15="Grupo 3",F15/E44,L15="Grupo 4",F15/E45,L15="Grupo 5",F15/E46) -> 0 | I15: =IFS(L15="Grupo 0",0,L15="Grupo 1",M15/M42,L15="Grupo 2",M15/M43,L15="Grupo 3",M15/M44,L15="Grupo 4",M15/M45,L15="Grupo 5",M15/M46) -> 0 | J15: =IFS(L15="Grupo 0",0,L15="Grupo 1",K15/K42,L15="Grupo 2",K15/K43,L15="Grupo 3",K15/K44,L15="Grupo 4",K15/K45,L15="Grupo 5",K15/K46) -> 0 | K15: =IFS(L15="Grupo 0",0,L15="Grupo 1",(E42*I15-F15)*N15,L15="Grupo 2",(E43*I15-F15)*N15,L15="Grupo 3",(E44*I15-F15)*N15,L15="Grupo 4",(E45*I15-F15)*N15,L15="Grupo 5",(E46*I15-F15)*N15) -> 0 | L15: Grupo 0 | N15: =IF(I15<H15,0,1) -> 1 | O15: =IFS(L15="Grupo 0",0,L15="Grupo 1",J15*D42,L15="Grupo 2",J15*D43,L15="Grupo 3",J15*D44,L15="Grupo 4",J15*D45,L15="Grupo 5",J15*D46) -> 0 | P15: =(F15+O15)/D41 -> 0
A16: 15 | F16: =D16*E16 -> 0 | G16: =IFS(L16="Grupo 0",0,L16="Grupo 1",F16/F42,L16="Grupo 2",F16/F43,L16="Grupo 3",F16/F44,L16="Grupo 4",F16/F45,L16="Grupo 5",F16/F46) -> 0 | H16: =IFS(L16="Grupo 0",0,L16="Grupo 1",F16/E42,L16="Grupo 2",F16/E43,L16="Grupo 3",F16/E44,L16="Grupo 4",F16/E45,L16="Grupo 5",F16/E46) -> 0 | I16: =IFS(L16="Grupo 0",0,L16="Grupo 1",M16/M42,L16="Grupo 2",M16/M43,L16="Grupo 3",M16/M44,L16="Grupo 4",M16/M45,L16="Grupo 5",M16/M46) -> 0 | J16: =IFS(L16="Grupo 0",0,L16="Grupo 1",K16/K42,L16="Grupo 2",K16/K43,L16="Grupo 3",K16/K44,L16="Grupo 4",K16/K45,L16="Grupo 5",K16/K46) -> 0 | K16: =IFS(L16="Grupo 0",0,L16="Grupo 1",(E42*I16-F16)*N16,L16="Grupo 2",(E43*I16-F16)*N16,L16="Grupo 3",(E44*I16-F16)*N16,L16="Grupo 4",(E45*I16-F16)*N16,L16="Grupo 5",(E46*I16-F16)*N16) -> 0 | L16: Grupo 0 | N16: =IF(I16<H16,0,1) -> 1 | O16: =IFS(L16="Grupo 0",0,L16="Grupo 1",J16*D42,L16="Grupo 2",J16*D43,L16="Grupo 3",J16*D44,L16="Grupo 4",J16*D45,L16="Grupo 5",J16*D46) -> 0 | P16: =(F16+O16)/D41 -> 0
A17: 16 | F17: =D17*E17 -> 0 | G17: =IFS(L17="Grupo 0",0,L17="Grupo 1",F17/F42,L17="Grupo 2",F17/F43,L17="Grupo 3",F17/F44,L17="Grupo 4",F17/F45,L17="Grupo 5",F17/F46) -> 0 | H17: =IFS(L17="Grupo 0",0,L17="Grupo 1",F17/E42,L17="Grupo 2",F17/E43,L17="Grupo 3",F17/E44,L17="Grupo 4",F17/E45,L17="Grupo 5",F17/E46) -> 0 | I17: =IFS(L17="Grupo 0",0,L17="Grupo 1",M17/M42,L17="Grupo 2",M17/M43,L17="Grupo 3",M17/M44,L17="Grupo 4",M17/M45,L17="Grupo 5",M17/M46) -> 0 | J17: =IFS(L17="Grupo 0",0,L17="Grupo 1",K17/K42,L17="Grupo 2",K17/K43,L17="Grupo 3",K17/K44,L17="Grupo 4",K17/K45,L17="Grupo 5",K17/K46) -> 0 | K17: =IFS(L17="Grupo 0",0,L17="Grupo 1",(E42*I17-F17)*N17,L17="Grupo 2",(E43*I17-F17)*N17,L17="Grupo 3",(E44*I17-F17)*N17,L17="Grupo 4",(E45*I17-F17)*N17,L17="Grupo 5",(E46*I17-F17)*N17) -> 0 | L17: Grupo 0 | N17: =IF(I17<H17,0,1) -> 1 | O17: =IFS(L17="Grupo 0",0,L17="Grupo 1",J17*D42,L17="Grupo 2",J17*D43,L17="Grupo 3",J17*D44,L17="Grupo 4",J17*D45,L17="Grupo 5",J17*D46) -> 0 | P17: =(F17+O17)/D41 -> 0
A18: 17 | F18: =D18*E18 -> 0 | G18: =IFS(L18="Grupo 0",0,L18="Grupo 1",F18/F42,L18="Grupo 2",F18/F43,L18="Grupo 3",F18/F44,L18="Grupo 4",F18/F45,L18="Grupo 5",F18/F46) -> 0 | H18: =IFS(L18="Grupo 0",0,L18="Grupo 1",F18/E42,L18="Grupo 2",F18/E43,L18="Grupo 3",F18/E44,L18="Grupo 4",F18/E45,L18="Grupo 5",F18/E46) -> 0 | I18: =IFS(L18="Grupo 0",0,L18="Grupo 1",M18/M42,L18="Grupo 2",M18/M43,L18="Grupo 3",M18/M44,L18="Grupo 4",M18/M45,L18="Grupo 5",M18/M46) -> 0 | J18: =IFS(L18="Grupo 0",0,L18="Grupo 1",K18/K42,L18="Grupo 2",K18/K43,L18="Grupo 3",K18/K44,L18="Grupo 4",K18/K45,L18="Grupo 5",K18/K46) -> 0 | K18: =IFS(L18="Grupo 0",0,L18="Grupo 1",(E42*I18-F18)*N18,L18="Grupo 2",(E43*I18-F18)*N18,L18="Grupo 3",(E44*I18-F18)*N18,L18="Grupo 4",(E45*I18-F18)*N18,L18="Grupo 5",(E46*I18-F18)*N18) -> 0 | L18: Grupo 0 | N18: =IF(I18<H18,0,1) -> 1 | O18: =IFS(L18="Grupo 0",0,L18="Grupo 1",J18*D42,L18="Grupo 2",J18*D43,L18="Grupo 3",J18*D44,L18="Grupo 4",J18*D45,L18="Grupo 5",J18*D46) -> 0 | P18: =(F18+O18)/D41 -> 0
A19: 18 | F19: =D19*E19 -> 0 | G19: =IFS(L19="Grupo 0",0,L19="Grupo 1",F19/F42,L19="Grupo 2",F19/F43,L19="Grupo 3",F19/F44,L19="Grupo 4",F19/F45,L19="Grupo 5",F19/F46) -> 0 | H19: =IFS(L19="Grupo 0",0,L19="Grupo 1",F19/E42,L19="Grupo 2",F19/E43,L19="Grupo 3",F19/E44,L19="Grupo 4",F19/E45,L19="Grupo 5",F19/E46) -> 0 | I19: =IFS(L19="Grupo 0",0,L19="Grupo 1",M19/M42,L19="Grupo 2",M19/M43,L19="Grupo 3",M19/M44,L19="Grupo 4",M19/M45,L19="Grupo 5",M19/M46) -> 0 | J19: =IFS(L19="Grupo 0",0,L19="Grupo 1",K19/K42,L19="Grupo 2",K19/K43,L19="Grupo 3",K19/K44,L19="Grupo 4",K19/K45,L19="Grupo 5",K19/K46) -> 0 | K19: =IFS(L19="Grupo 0",0,L19="Grupo 1",(E42*I19-F19)*N19,L19="Grupo 2",(E43*I19-F19)*N19,L19="Grupo 3",(E44*I19-F19)*N19,L19="Grupo 4",(E45*I19-F19)*N19,L19="Grupo 5",(E46*I19-F19)*N19) -> 0 | L19: Grupo 0 | N19: =IF(I19<H19,0,1) -> 1 | O19: =IFS(L19="Grupo 0",0,L19="Grupo 1",J19*D42,L19="Grupo 2",J19*D43,L19="Grupo 3",J19*D44,L19="Grupo 4",J19*D45,L19="Grupo 5",J19*D46) -> 0 | P19: =(F19+O19)/D41 -> 0
A20: 19 | F20: =D20*E20 -> 0 | G20: =IFS(L20="Grupo 0",0,L20="Grupo 1",F20/F42,L20="Grupo 2",F20/F43,L20="Grupo 3",F20/F44,L20="Grupo 4",F20/F45,L20="Grupo 5",F20/F46) -> 0 | H20: =IFS(L20="Grupo 0",0,L20="Grupo 1",F20/E42,L20="Grupo 2",F20/E43,L20="Grupo 3",F20/E44,L20="Grupo 4",F20/E45,L20="Grupo 5",F20/E46) -> 0 | I20: =IFS(L20="Grupo 0",0,L20="Grupo 1",M20/M42,L20="Grupo 2",M20/M43,L20="Grupo 3",M20/M44,L20="Grupo 4",M20/M45,L20="Grupo 5",M20/M46) -> 0 | J20: =IFS(L20="Grupo 0",0,L20="Grupo 1",K20/K42,L20="Grupo 2",K20/K43,L20="Grupo 3",K20/K44,L20="Grupo 4",K20/K45,L20="Grupo 5",K20/K46) -> 0 | K20: =IFS(L20="Grupo 0",0,L20="Grupo 1",(E42*I20-F20)*N20,L20="Grupo 2",(E43*I20-F20)*N20,L20="Grupo 3",(E44*I20-F20)*N20,L20="Grupo 4",(E45*I20-F20)*N20,L20="Grupo 5",(E46*I20-F20)*N20) -> 0 | L20: Grupo 0 | N20: =IF(I20<H20,0,1) -> 1 | O20: =IFS(L20="Grupo 0",0,L20="Grupo 1",J20*D42,L20="Grupo 2",J20*D43,L20="Grupo 3",J20*D44,L20="Grupo 4",J20*D45,L20="Grupo 5",J20*D46) -> 0 | P20: =(F20+O20)/D41 -> 0
A21: 20 | F21: =D21*E21 -> 0 | G21: =IFS(L21="Grupo 0",0,L21="Grupo 1",F21/F42,L21="Grupo 2",F21/F43,L21="Grupo 3",F21/F44,L21="Grupo 4",F21/F45,L21="Grupo 5",F21/F46) -> 0 | H21: =IFS(L21="Grupo 0",0,L21="Grupo 1",F21/E42,L21="Grupo 2",F21/E43,L21="Grupo 3",F21/E44,L21="Grupo 4",F21/E45,L21="Grupo 5",F21/E46) -> 0 | I21: =IFS(L21="Grupo 0",0,L21="Grupo 1",M21/M42,L21="Grupo 2",M21/M43,L21="Grupo 3",M21/M44,L21="Grupo 4",M21/M45,L21="Grupo 5",M21/M46) -> 0 | J21: =IFS(L21="Grupo 0",0,L21="Grupo 1",K21/K42,L21="Grupo 2",K21/K43,L21="Grupo 3",K21/K44,L21="Grupo 4",K21/K45,L21="Grupo 5",K21/K46) -> 0 | K21: =IFS(L21="Grupo 0",0,L21="Grupo 1",(E42*I21-F21)*N21,L21="Grupo 2",(E43*I21-F21)*N21,L21="Grupo 3",(E44*I20-F21)*N21,L21="Grupo 4",(E45*I21-F21)*N21,L21="Grupo 5",(E46*I21-F21)*N21) -> 0 | L21: Grupo 0 | N21: =IF(I21<H21,0,1) -> 1 | O21: =IFS(L21="Grupo 0",0,L21="Grupo 1",J21*D42,L21="Grupo 2",J21*D43,L21="Grupo 3",J21*D44,L21="Grupo 4",J21*D45,L21="Grupo 5",J21*D46) -> 0 | P21: =(F21+O21)/D41 -> 0
A22: 21 | F22: =D22*E22 -> 0 | G22: =IFS(L22="Grupo 0",0,L22="Grupo 1",F22/F42,L22="Grupo 2",F22/F43,L22="Grupo 3",F22/F44,L22="Grupo 4",F22/F45,L22="Grupo 5",F22/F46) -> 0 | H22: =IFS(L22="Grupo 0",0,L22="Grupo 1",F22/E42,L22="Grupo 2",F22/E43,L22="Grupo 3",F22/E44,L22="Grupo 4",F22/E45,L22="Grupo 5",F22/E46) -> 0 | I22: =IFS(L22="Grupo 0",0,L22="Grupo 1",M22/M42,L22="Grupo 2",M22/M43,L22="Grupo 3",M22/M44,L22="Grupo 4",M22/M45,L22="Grupo 5",M22/M46) -> 0 | J22: =IFS(L22="Grupo 0",0,L22="Grupo 1",K22/K42,L22="Grupo 2",K22/K43,L22="Grupo 3",K22/K44,L22="Grupo 4",K22/K45,L22="Grupo 5",K22/K46) -> 0 | K22: =IFS(L22="Grupo 0",0,L22="Grupo 1",(E42*I22-F22)*N22,L22="Grupo 2",(E43*I22-F22)*N22,L22="Grupo 3",(E44*I22-F22)*N22,L22="Grupo 4",(E45*I22-F22)*N22,L22="Grupo 5",(E46*I22-F22)*N22) -> 0 | L22: Grupo 0 | N22: =IF(I22<H22,0,1) -> 1 | O22: =IFS(L22="Grupo 0",0,L22="Grupo 1",J22*D42,L22="Grupo 2",J22*D43,L22="Grupo 3",J22*D44,L22="Grupo 4",J22*D45,L22="Grupo 5",J22*D46) -> 0
A23: 22 | F23: =D23*E23 -> 0 | G23: =IFS(L23="Grupo 0",0,L23="Grupo 1",F23/F42,L23="Grupo 2",F23/F43,L23="Grupo 3",F23/F44,L23="Grupo 4",F23/F45,L23="Grupo 5",F23/F46) -> 0 | H23: =IFS(L23="Grupo 0",0,L23="Grupo 1",F23/E42,L23="Grupo 2",F23/E43,L23="Grupo 3",F23/E44,L23="Grupo 4",F23/E45,L23="Grupo 5",F23/E46) -> 0 | I23: =IFS(L23="Grupo 0",0,L23="Grupo 1",M23/M42,L23="Grupo 2",M23/M43,L23="Grupo 3",M23/M44,L23="Grupo 4",M23/M45,L23="Grupo 5",M23/M46) -> 0 | J23: =IFS(L23="Grupo 0",0,L23="Grupo 1",K23/K42,L23="Grupo 2",K23/K43,L23="Grupo 3",K23/K44,L23="Grupo 4",K23/K45,L23="Grupo 5",K23/K46) -> 0 | K23: =IFS(L23="Grupo 0",0,L23="Grupo 1",(E42*I23-F23)*N23,L23="Grupo 2",(E43*I23-F23)*N23,L23="Grupo 3",(E44*I23-F23)*N23,L23="Grupo 4",(E45*I23-F23)*N23,L23="Grupo 5",(E46*I23-F23)*N23) -> 0 | L23: Grupo 0 | N23: =IF(I23<H23,0,1) -> 1 | O23: =IFS(L23="Grupo 0",0,L23="Grupo 1",J23*D42,L23="Grupo 2",J23*D43,L23="Grupo 3",J23*D44,L23="Grupo 4",J23*D45,L23="Grupo 5",J23*D46) -> 0
A24: 23 | F24: =D24*E24 -> 0 | G24: =IFS(L24="Grupo 0",0,L24="Grupo 1",F24/F42,L24="Grupo 2",F24/F43,L24="Grupo 3",F24/F44,L24="Grupo 4",F24/F45,L24="Grupo 5",F24/F46) -> 0 | H24: =IFS(L24="Grupo 0",0,L24="Grupo 1",F24/E42,L24="Grupo 2",F24/E43,L24="Grupo 3",F24/E44,L24="Grupo 4",F24/E45,L24="Grupo 5",F24/E46) -> 0 | I24: =IFS(L24="Grupo 0",0,L24="Grupo 1",M24/M42,L24="Grupo 2",M24/M43,L24="Grupo 3",M24/M44,L24="Grupo 4",M24/M45,L24="Grupo 5",M24/M46) -> 0 | J24: =IFS(L24="Grupo 0",0,L24="Grupo 1",K24/K42,L24="Grupo 2",K24/K43,L24="Grupo 3",K24/K44,L24="Grupo 4",K24/K45,L24="Grupo 5",K24/K46) -> 0 | K24: =IFS(L24="Grupo 0",0,L24="Grupo 1",(E42*I24-F24)*N24,L24="Grupo 2",(E43*I24-F24)*N24,L24="Grupo 3",(E44*I24-F24)*N24,L24="Grupo 4",(E45*I24-F24)*N24,L24="Grupo 5",(E46*I24-F24)*N24) -> 0 | L24: Grupo 0 | N24: =IF(I24<H24,0,1) -> 1 | O24: =IFS(L24="Grupo 0",0,L24="Grupo 1",J24*D42,L24="Grupo 2",J24*D43,L24="Grupo 3",J24*D44,L24="Grupo 4",J24*D45,L24="Grupo 5",J24*D46) -> 0
A25: 24 | F25: =D25*E25 -> 0 | G25: =IFS(L25="Grupo 0",0,L25="Grupo 1",F25/F42,L25="Grupo 2",F25/F43,L25="Grupo 3",F25/F44,L25="Grupo 4",F25/F45,L25="Grupo 5",F25/F46) -> 0 | H25: =IFS(L25="Grupo 0",0,L25="Grupo 1",F25/E42,L25="Grupo 2",F25/E43,L25="Grupo 3",F25/E44,L25="Grupo 4",F25/E45,L25="Grupo 5",F25/E46) -> 0 | I25: =IFS(L25="Grupo 0",0,L25="Grupo 1",M25/M42,L25="Grupo 2",M25/M43,L25="Grupo 3",M25/M44,L25="Grupo 4",M25/M45,L25="Grupo 5",M25/M46) -> 0 | J25: =IFS(L25="Grupo 0",0,L25="Grupo 1",K25/K42,L25="Grupo 2",K25/K43,L25="Grupo 3",K25/K44,L25="Grupo 4",K25/K45,L25="Grupo 5",K25/K46) -> 0 | K25: =IFS(L25="Grupo 0",0,L25="Grupo 1",(E42*I25-F25)*N25,L25="Grupo 2",(E43*I25-F25)*N25,L25="Grupo 3",(E44*I25-F25)*N25,L25="Grupo 4",(E45*I25-F25)*N25,L25="Grupo 5",(E46*I25-F25)*N25) -> 0 | L25: Grupo 0 | N25: =IF(I25<H25,0,1) -> 1 | O25: =IFS(L25="Grupo 0",0,L25="Grupo 1",J25*D42,L25="Grupo 2",J25*D43,L25="Grupo 3",J25*D44,L25="Grupo 4",J25*D45,L25="Grupo 5",J25*D46) -> 0
A26: 25 | F26: =D26*E26 -> 0 | G26: =IFS(L26="Grupo 0",0,L26="Grupo 1",F26/F42,L26="Grupo 2",F26/F43,L26="Grupo 3",F26/F44,L26="Grupo 4",F26/F45,L26="Grupo 5",F26/F46) -> 0 | H26: =IFS(L26="Grupo 0",0,L26="Grupo 1",F26/E42,L26="Grupo 2",F26/E43,L26="Grupo 3",F26/E44,L26="Grupo 4",F26/E45,L26="Grupo 5",F26/E46) -> 0 | I26: =IFS(L26="Grupo 0",0,L26="Grupo 1",M26/M42,L26="Grupo 2",M26/M43,L26="Grupo 3",M26/M44,L26="Grupo 4",M26/M45,L26="Grupo 5",M26/M46) -> 0 | J26: =IFS(L26="Grupo 0",0,L26="Grupo 1",K26/K42,L26="Grupo 2",K26/K43,L26="Grupo 3",K26/K44,L26="Grupo 4",K26/K45,L26="Grupo 5",K26/K46) -> 0 | K26: =IFS(L26="Grupo 0",0,L26="Grupo 1",(E42*I26-F26)*N26,L26="Grupo 2",(E43*I26-F26)*N26,L26="Grupo 3",(E44*I26-F26)*N26,L26="Grupo 4",(E45*I26-F26)*N26,L26="Grupo 5",(E46*I26-F26)*N26) -> 0 | L26: Grupo 0 | N26: =IF(I26<H26,0,1) -> 1 | O26: =IFS(L26="Grupo 0",0,L26="Grupo 1",J26*D42,L26="Grupo 2",J26*D43,L26="Grupo 3",J26*D44,L26="Grupo 4",J26*D45,L26="Grupo 5",J26*D46) -> 0
A27: 26 | F27: =D27*E27 -> 0 | G27: =IFS(L27="Grupo 0",0,L27="Grupo 1",F27/F42,L27="Grupo 2",F27/F43,L27="Grupo 3",F27/F44,L27="Grupo 4",F27/F45,L27="Grupo 5",F27/F46) -> 0 | H27: =IFS(L27="Grupo 0",0,L27="Grupo 1",F27/E42,L27="Grupo 2",F27/E43,L27="Grupo 3",F27/E44,L27="Grupo 4",F27/E45,L27="Grupo 5",F27/E46) -> 0 | I27: =IFS(L27="Grupo 0",0,L27="Grupo 1",M27/M42,L27="Grupo 2",M27/M43,L27="Grupo 3",M27/M44,L27="Grupo 4",M27/M45,L27="Grupo 5",M27/M46) -> 0 | J27: =IFS(L27="Grupo 0",0,L27="Grupo 1",K27/K42,L27="Grupo 2",K27/K43,L27="Grupo 3",K27/K44,L27="Grupo 4",K27/K45,L27="Grupo 5",K27/K46) -> 0 | K27: =IFS(L27="Grupo 0",0,L27="Grupo 1",(E42*I27-F27)*N27,L27="Grupo 2",(E43*I27-F27)*N27,L27="Grupo 3",(E44*I27-F27)*N27,L27="Grupo 4",(E45*I27-F27)*N27,L27="Grupo 5",(E46*I27-F27)*N27) -> 0 | L27: Grupo 0 | N27: =IF(I27<H27,0,1) -> 1 | O27: =IFS(L27="Grupo 0",0,L27="Grupo 1",J27*D42,L27="Grupo 2",J27*D43,L27="Grupo 3",J27*D44,L27="Grupo 4",J27*D45,L27="Grupo 5",J27*D46) -> 0
A28: 27 | F28: =D28*E28 -> 0 | G28: =IFS(L28="Grupo 0",0,L28="Grupo 1",F28/F42,L28="Grupo 2",F28/F43,L28="Grupo 3",F28/F44,L28="Grupo 4",F28/F45,L28="Grupo 5",F28/F46) -> 0 | H28: =IFS(L28="Grupo 0",0,L28="Grupo 1",F28/E42,L28="Grupo 2",F28/E43,L28="Grupo 3",F28/E44,L28="Grupo 4",F28/E45,L28="Grupo 5",F28/E46) -> 0 | I28: =IFS(L28="Grupo 0",0,L28="Grupo 1",M28/M42,L28="Grupo 2",M28/M43,L28="Grupo 3",M28/M44,L28="Grupo 4",M28/M45,L28="Grupo 5",M28/M46) -> 0 | J28: =IFS(L28="Grupo 0",0,L28="Grupo 1",K28/K42,L28="Grupo 2",K28/K43,L28="Grupo 3",K28/K44,L28="Grupo 4",K28/K45,L28="Grupo 5",K28/K46) -> 0 | K28: =IFS(L28="Grupo 0",0,L28="Grupo 1",(E42*I28-F28)*N28,L28="Grupo 2",(E43*I28-F28)*N28,L28="Grupo 3",(E44*I28-F28)*N28,L28="Grupo 4",(E45*I28-F28)*N28,L28="Grupo 5",(E46*I28-F28)*N28) -> 0 | L28: Grupo 0 | N28: =IF(I28<H28,0,1) -> 1 | O28: =IFS(L28="Grupo 0",0,L28="Grupo 1",J28*D42,L28="Grupo 2",J28*D43,L28="Grupo 3",J28*D44,L28="Grupo 4",J28*D45,L28="Grupo 5",J28*D46) -> 0
A29: 28 | F29: =D29*E29 -> 0 | G29: =IFS(L29="Grupo 0",0,L29="Grupo 1",F29/F42,L29="Grupo 2",F29/F43,L29="Grupo 3",F29/F44,L29="Grupo 4",F29/F45,L29="Grupo 5",F29/F46) -> 0 | H29: =IFS(L29="Grupo 0",0,L29="Grupo 1",F29/E42,L29="Grupo 2",F29/E43,L29="Grupo 3",F29/E44,L29="Grupo 4",F29/E45,L29="Grupo 5",F29/E46) -> 0 | I29: =IFS(L29="Grupo 0",0,L29="Grupo 1",M29/M42,L29="Grupo 2",M29/M43,L29="Grupo 3",M29/M44,L29="Grupo 4",M29/M45,L29="Grupo 5",M29/M46) -> 0 | J29: =IFS(L29="Grupo 0",0,L29="Grupo 1",K29/K42,L29="Grupo 2",K29/K43,L29="Grupo 3",K29/K44,L29="Grupo 4",K29/K45,L29="Grupo 5",K29/K46) -> 0 | K29: =IFS(L29="Grupo 0",0,L29="Grupo 1",(E42*I29-F29)*N29,L29="Grupo 2",(E43*I29-F29)*N29,L29="Grupo 3",(E44*I29-F29)*N29,L29="Grupo 4",(E45*I29-F29)*N29,L29="Grupo 5",(E46*I29-F29)*N29) -> 0 | L29: Grupo 0 | N29: =IF(I29<H29,0,1) -> 1 | O29: =IFS(L29="Grupo 0",0,L29="Grupo 1",J29*D42,L29="Grupo 2",J29*D43,L29="Grupo 3",J29*D44,L29="Grupo 4",J29*D45,L29="Grupo 5",J29*D46) -> 0
A30: 29 | F30: =D30*E30 -> 0 | G30: =IFS(L30="Grupo 0",0,L30="Grupo 1",F30/F42,L30="Grupo 2",F30/F43,L30="Grupo 3",F30/F44,L30="Grupo 4",F30/F45,L30="Grupo 5",F30/F46) -> 0 | H30: =IFS(L30="Grupo 0",0,L30="Grupo 1",F30/E42,L30="Grupo 2",F30/E43,L30="Grupo 3",F30/E44,L30="Grupo 4",F30/E45,L30="Grupo 5",F30/E46) -> 0 | I30: =IFS(L30="Grupo 0",0,L30="Grupo 1",M30/M42,L30="Grupo 2",M30/M43,L30="Grupo 3",M30/M44,L30="Grupo 4",M30/M45,L30="Grupo 5",M30/M46) -> 0 | J30: =IFS(L30="Grupo 0",0,L30="Grupo 1",K30/K42,L30="Grupo 2",K30/K43,L30="Grupo 3",K30/K44,L30="Grupo 4",K30/K45,L30="Grupo 5",K30/K46) -> 0 | K30: =IFS(L30="Grupo 0",0,L30="Grupo 1",(E42*I30-F30)*N30,L30="Grupo 2",(E43*I30-F30)*N30,L30="Grupo 3",(E44*I30-F30)*N30,L30="Grupo 4",(E45*I30-F30)*N30,L30="Grupo 5",(E46*I30-F30)*N30) -> 0 | L30: Grupo 0 | N30: =IF(I30<H30,0,1) -> 1 | O30: =IFS(L30="Grupo 0",0,L30="Grupo 1",J30*D42,L30="Grupo 2",J30*D43,L30="Grupo 3",J30*D44,L30="Grupo 4",J30*D45,L30="Grupo 5",J30*D46) -> 0
A31: 30 | F31: =D31*E31 -> 0 | G31: =IFS(L31="Grupo 0",0,L31="Grupo 1",F31/F42,L31="Grupo 2",F31/F43,L31="Grupo 3",F31/F44,L31="Grupo 4",F31/F45,L31="Grupo 5",F31/F46) -> 0 | H31: =IFS(L31="Grupo 0",0,L31="Grupo 1",F31/E42,L31="Grupo 2",F31/E43,L31="Grupo 3",F31/E44,L31="Grupo 4",F31/E45,L31="Grupo 5",F31/E46) -> 0 | I31: =IFS(L31="Grupo 0",0,L31="Grupo 1",M31/M42,L31="Grupo 2",M31/M43,L31="Grupo 3",M31/M44,L31="Grupo 4",M31/M45,L31="Grupo 5",M31/M46) -> 0 | J31: =IFS(L31="Grupo 0",0,L31="Grupo 1",K31/K42,L31="Grupo 2",K31/K43,L31="Grupo 3",K31/K44,L31="Grupo 4",K31/K45,L31="Grupo 5",K31/K46) -> 0 | K31: =IFS(L31="Grupo 0",0,L31="Grupo 1",(E42*I31-F31)*N31,L31="Grupo 2",(E43*I31-F31)*N31,L31="Grupo 3",(E44*I30-F31)*N31,L31="Grupo 4",(E45*I31-F31)*N31,L31="Grupo 5",(E46*I31-F31)*N31) -> 0 | L31: Grupo 0 | N31: =IF(I31<H31,0,1) -> 1 | O31: =IFS(L31="Grupo 0",0,L31="Grupo 1",J31*D42,L31="Grupo 2",J31*D43,L31="Grupo 3",J31*D44,L31="Grupo 4",J31*D45,L31="Grupo 5",J31*D46) -> 0
A32: 31 | F32: =D32*E32 -> 0 | G32: =IFS(L32="Grupo 0",0,L32="Grupo 1",F32/F42,L32="Grupo 2",F32/F43,L32="Grupo 3",F32/F44,L32="Grupo 4",F32/F45,L32="Grupo 5",F32/F46) -> 0 | H32: =IFS(L32="Grupo 0",0,L32="Grupo 1",F32/E42,L32="Grupo 2",F32/E43,L32="Grupo 3",F32/E44,L32="Grupo 4",F32/E45,L32="Grupo 5",F32/E46) -> 0 | I32: =IFS(L32="Grupo 0",0,L32="Grupo 1",M32/M42,L32="Grupo 2",M32/M43,L32="Grupo 3",M32/M44,L32="Grupo 4",M32/M45,L32="Grupo 5",M32/M46) -> 0 | J32: =IFS(L32="Grupo 0",0,L32="Grupo 1",K32/K42,L32="Grupo 2",K32/K43,L32="Grupo 3",K32/K44,L32="Grupo 4",K32/K45,L32="Grupo 5",K32/K46) -> 0 | K32: =IFS(L32="Grupo 0",0,L32="Grupo 1",(E42*I32-F32)*N32,L32="Grupo 2",(E43*I32-F32)*N32,L32="Grupo 3",(E44*I32-F32)*N32,L32="Grupo 4",(E45*I32-F32)*N32,L32="Grupo 5",(E46*I32-F32)*N32) -> 0 | L32: Grupo 0 | N32: =IF(I32<H32,0,1) -> 1 | O32: =IFS(L32="Grupo 0",0,L32="Grupo 1",J32*D42,L32="Grupo 2",J32*D43,L32="Grupo 3",J32*D44,L32="Grupo 4",J32*D45,L32="Grupo 5",J32*D46) -> 0
A33: 32 | F33: =D33*E33 -> 0 | G33: =IFS(L33="Grupo 0",0,L33="Grupo 1",F33/F42,L33="Grupo 2",F33/F43,L33="Grupo 3",F33/F44,L33="Grupo 4",F33/F45,L33="Grupo 5",F33/F46) -> 0 | H33: =IFS(L33="Grupo 0",0,L33="Grupo 1",F33/E42,L33="Grupo 2",F33/E43,L33="Grupo 3",F33/E44,L33="Grupo 4",F33/E45,L33="Grupo 5",F33/E46) -> 0 | I33: =IFS(L33="Grupo 0",0,L33="Grupo 1",M33/M42,L33="Grupo 2",M33/M43,L33="Grupo 3",M33/M44,L33="Grupo 4",M33/M45,L33="Grupo 5",M33/M46) -> 0 | J33: =IFS(L33="Grupo 0",0,L33="Grupo 1",K33/K42,L33="Grupo 2",K33/K43,L33="Grupo 3",K33/K44,L33="Grupo 4",K33/K45,L33="Grupo 5",K33/K46) -> 0 | K33: =IFS(L33="Grupo 0",0,L33="Grupo 1",(E42*I33-F33)*N33,L33="Grupo 2",(E43*I33-F33)*N33,L33="Grupo 3",(E44*I33-F33)*N33,L33="Grupo 4",(E45*I33-F33)*N33,L33="Grupo 5",(E46*I33-F33)*N33) -> 0 | L33: Grupo 0 | N33: =IF(I33<H33,0,1) -> 1 | O33: =IFS(L33="Grupo 0",0,L33="Grupo 1",J33*D42,L33="Grupo 2",J33*D43,L33="Grupo 3",J33*D44,L33="Grupo 4",J33*D45,L33="Grupo 5",J33*D46) -> 0
A34: 33 | F34: =D34*E34 -> 0 | G34: =IFS(L34="Grupo 0",0,L34="Grupo 1",F34/F42,L34="Grupo 2",F34/F43,L34="Grupo 3",F34/F44,L34="Grupo 4",F34/F45,L34="Grupo 5",F34/F46) -> 0 | H34: =IFS(L34="Grupo 0",0,L34="Grupo 1",F34/E42,L34="Grupo 2",F34/E43,L34="Grupo 3",F34/E44,L34="Grupo 4",F34/E45,L34="Grupo 5",F34/E46) -> 0 | I34: =IFS(L34="Grupo 0",0,L34="Grupo 1",M34/M42,L34="Grupo 2",M34/M43,L34="Grupo 3",M34/M44,L34="Grupo 4",M34/M45,L34="Grupo 5",M34/M46) -> 0 | J34: =IFS(L34="Grupo 0",0,L34="Grupo 1",K34/K42,L34="Grupo 2",K34/K43,L34="Grupo 3",K34/K44,L34="Grupo 4",K34/K45,L34="Grupo 5",K34/K46) -> 0 | K34: =IFS(L34="Grupo 0",0,L34="Grupo 1",(E42*I34-F34)*N34,L34="Grupo 2",(E43*I34-F34)*N34,L34="Grupo 3",(E44*I34-F34)*N34,L34="Grupo 4",(E45*I34-F34)*N34,L34="Grupo 5",(E46*I34-F34)*N34) -> 0 | L34: Grupo 0 | N34: =IF(I34<H34,0,1) -> 1 | O34: =IFS(L34="Grupo 0",0,L34="Grupo 1",J34*D42,L34="Grupo 2",J34*D43,L34="Grupo 3",J34*D44,L34="Grupo 4",J34*D45,L34="Grupo 5",J34*D46) -> 0
A35: 34 | F35: =D35*E35 -> 0 | G35: =IFS(L35="Grupo 0",0,L35="Grupo 1",F35/F42,L35="Grupo 2",F35/F43,L35="Grupo 3",F35/F44,L35="Grupo 4",F35/F45,L35="Grupo 5",F35/F46) -> 0 | H35: =IFS(L35="Grupo 0",0,L35="Grupo 1",F35/E42,L35="Grupo 2",F35/E43,L35="Grupo 3",F35/E44,L35="Grupo 4",F35/E45,L35="Grupo 5",F35/E46) -> 0 | I35: =IFS(L35="Grupo 0",0,L35="Grupo 1",M35/M42,L35="Grupo 2",M35/M43,L35="Grupo 3",M35/M44,L35="Grupo 4",M35/M45,L35="Grupo 5",M35/M46) -> 0 | J35: =IFS(L35="Grupo 0",0,L35="Grupo 1",K35/K42,L35="Grupo 2",K35/K43,L35="Grupo 3",K35/K44,L35="Grupo 4",K35/K45,L35="Grupo 5",K35/K46) -> 0 | K35: =IFS(L35="Grupo 0",0,L35="Grupo 1",(E42*I35-F35)*N35,L35="Grupo 2",(E43*I35-F35)*N35,L35="Grupo 3",(E44*I35-F35)*N35,L35="Grupo 4",(E45*I35-F35)*N35,L35="Grupo 5",(E46*I35-F35)*N35) -> 0 | L35: Grupo 0 | N35: =IF(I35<H35,0,1) -> 1 | O35: =IFS(L35="Grupo 0",0,L35="Grupo 1",J35*D42,L35="Grupo 2",J35*D43,L35="Grupo 3",J35*D44,L35="Grupo 4",J35*D45,L35="Grupo 5",J35*D46) -> 0
A36: 35 | F36: =D36*E36 -> 0 | G36: =IFS(L36="Grupo 0",0,L36="Grupo 1",F36/F42,L36="Grupo 2",F36/F43,L36="Grupo 3",F36/F44,L36="Grupo 4",F36/F45,L36="Grupo 5",F36/F46) -> 0 | H36: =IFS(L36="Grupo 0",0,L36="Grupo 1",F36/E42,L36="Grupo 2",F36/E43,L36="Grupo 3",F36/E44,L36="Grupo 4",F36/E45,L36="Grupo 5",F36/E46) -> 0 | I36: =IFS(L36="Grupo 0",0,L36="Grupo 1",M36/M42,L36="Grupo 2",M36/M43,L36="Grupo 3",M36/M44,L36="Grupo 4",M36/M45,L36="Grupo 5",M36/M46) -> 0 | J36: =IFS(L36="Grupo 0",0,L36="Grupo 1",K36/K42,L36="Grupo 2",K36/K43,L36="Grupo 3",K36/K44,L36="Grupo 4",K36/K45,L36="Grupo 5",K36/K46) -> 0 | K36: =IFS(L36="Grupo 0",0,L36="Grupo 1",(E42*I36-F36)*N36,L36="Grupo 2",(E43*I36-F36)*N36,L36="Grupo 3",(E44*I36-F36)*N36,L36="Grupo 4",(E45*I36-F36)*N36,L36="Grupo 5",(E46*I36-F36)*N36) -> 0 | L36: Grupo 0 | N36: =IF(I36<H36,0,1) -> 1 | O36: =IFS(L36="Grupo 0",0,L36="Grupo 1",J36*D42,L36="Grupo 2",J36*D43,L36="Grupo 3",J36*D44,L36="Grupo 4",J36*D45,L36="Grupo 5",J36*D46) -> 0
A37: 36 | F37: =D37*E37 -> 0 | G37: =IFS(L37="Grupo 0",0,L37="Grupo 1",F37/F42,L37="Grupo 2",F37/F43,L37="Grupo 3",F37/F44,L37="Grupo 4",F37/F45,L37="Grupo 5",F37/F46) -> 0 | H37: =IFS(L37="Grupo 0",0,L37="Grupo 1",F37/E42,L37="Grupo 2",F37/E43,L37="Grupo 3",F37/E44,L37="Grupo 4",F37/E45,L37="Grupo 5",F37/E46) -> 0 | I37: =IFS(L37="Grupo 0",0,L37="Grupo 1",M37/M42,L37="Grupo 2",M37/M43,L37="Grupo 3",M37/M44,L37="Grupo 4",M37/M45,L37="Grupo 5",M37/M46) -> 0 | J37: =IFS(L37="Grupo 0",0,L37="Grupo 1",K37/K42,L37="Grupo 2",K37/K43,L37="Grupo 3",K37/K44,L37="Grupo 4",K37/K45,L37="Grupo 5",K37/K46) -> 0 | K37: =IFS(L37="Grupo 0",0,L37="Grupo 1",(E42*I37-F37)*N37,L37="Grupo 2",(E43*I37-F37)*N37,L37="Grupo 3",(E44*I37-F37)*N37,L37="Grupo 4",(E45*I37-F37)*N37,L37="Grupo 5",(E46*I37-F37)*N37) -> 0 | L37: Grupo 0 | N37: =IF(I37<H37,0,1) -> 1 | O37: =IFS(L37="Grupo 0",0,L37="Grupo 1",J37*D42,L37="Grupo 2",J37*D43,L37="Grupo 3",J37*D44,L37="Grupo 4",J37*D45,L37="Grupo 5",J37*D46) -> 0
A38: 37 | F38: =D38*E38 -> 0 | G38: =IFS(L38="Grupo 0",0,L38="Grupo 1",F38/F42,L38="Grupo 2",F38/F43,L38="Grupo 3",F38/F44,L38="Grupo 4",F38/F45,L38="Grupo 5",F38/F46) -> 0 | H38: =IFS(L38="Grupo 0",0,L38="Grupo 1",F38/E42,L38="Grupo 2",F38/E43,L38="Grupo 3",F38/E44,L38="Grupo 4",F38/E45,L38="Grupo 5",F38/E46) -> 0 | I38: =IFS(L38="Grupo 0",0,L38="Grupo 1",M38/M42,L38="Grupo 2",M38/M43,L38="Grupo 3",M38/M44,L38="Grupo 4",M38/M45,L38="Grupo 5",M38/M46) -> 0 | J38: =IFS(L38="Grupo 0",0,L38="Grupo 1",K38/K42,L38="Grupo 2",K38/K43,L38="Grupo 3",K38/K44,L38="Grupo 4",K38/K45,L38="Grupo 5",K38/K46) -> 0 | K38: =IFS(L38="Grupo 0",0,L38="Grupo 1",(E42*I38-F38)*N38,L38="Grupo 2",(E43*I38-F38)*N38,L38="Grupo 3",(E44*I38-F38)*N38,L38="Grupo 4",(E45*I38-F38)*N38,L38="Grupo 5",(E46*I38-F38)*N38) -> 0 | L38: Grupo 0 | N38: =IF(I38<H38,0,1) -> 1 | O38: =IFS(L38="Grupo 0",0,L38="Grupo 1",J38*D42,L38="Grupo 2",J38*D43,L38="Grupo 3",J38*D44,L38="Grupo 4",J38*D45,L38="Grupo 5",J38*D46) -> 0
A39: 38 | F39: =D39*E39 -> 0 | G39: =IFS(L39="Grupo 0",0,L39="Grupo 1",F39/F42,L39="Grupo 2",F39/F43,L39="Grupo 3",F39/F44,L39="Grupo 4",F39/F45,L39="Grupo 5",F39/F46) -> 0 | H39: =IFS(L39="Grupo 0",0,L39="Grupo 1",F39/E42,L39="Grupo 2",F39/E43,L39="Grupo 3",F39/E44,L39="Grupo 4",F39/E45,L39="Grupo 5",F39/E46) -> 0 | I39: =IFS(L39="Grupo 0",0,L39="Grupo 1",M39/M42,L39="Grupo 2",M39/M43,L39="Grupo 3",M39/M44,L39="Grupo 4",M39/M45,L39="Grupo 5",M39/M46) -> 0 | J39: =IFS(L39="Grupo 0",0,L39="Grupo 1",K39/K42,L39="Grupo 2",K39/K43,L39="Grupo 3",K39/K44,L39="Grupo 4",K39/K45,L39="Grupo 5",K39/K46) -> 0 | K39: =IFS(L39="Grupo 0",0,L39="Grupo 1",(E42*I39-F39)*N39,L39="Grupo 2",(E43*I39-F39)*N39,L39="Grupo 3",(E44*I39-F39)*N39,L39="Grupo 4",(E45*I39-F39)*N39,L39="Grupo 5",(E46*I39-F39)*N39) -> 0 | L39: Grupo 0 | N39: =IF(I39<H39,0,1) -> 1 | O39: =IFS(L39="Grupo 0",0,L39="Grupo 1",J39*D42,L39="Grupo 2",J39*D43,L39="Grupo 3",J39*D44,L39="Grupo 4",J39*D45,L39="Grupo 5",J39*D46) -> 0
A40: 39 | F40: =D40*E40 -> 0 | G40: =IFS(L40="Grupo 0",0,L40="Grupo 1",F40/F42,L40="Grupo 2",F40/F43,L40="Grupo 3",F40/F44,L40="Grupo 4",F40/F45,L40="Grupo 5",F40/F46) -> 0 | H40: =IFS(L40="Grupo 0",0,L40="Grupo 1",F40/E42,L40="Grupo 2",F40/E43,L40="Grupo 3",F40/E44,L40="Grupo 4",F40/E45,L40="Grupo 5",F40/E46) -> 0 | I40: =IFS(L40="Grupo 0",0,L40="Grupo 1",M40/M42,L40="Grupo 2",M40/M43,L40="Grupo 3",M40/M44,L40="Grupo 4",M40/M45,L40="Grupo 5",M40/M46) -> 0 | J40: =IFS(L40="Grupo 0",0,L40="Grupo 1",K40/K42,L40="Grupo 2",K40/K43,L40="Grupo 3",K40/K44,L40="Grupo 4",K40/K45,L40="Grupo 5",K40/K46) -> 0 | K40: =IFS(L40="Grupo 0",0,L40="Grupo 1",(E42*I40-F40)*N40,L40="Grupo 2",(E43*I40-F40)*N40,L40="Grupo 3",(E44*I40-F40)*N40,L40="Grupo 4",(E45*I40-F40)*N40,L40="Grupo 5",(E46*I40-F40)*N40) -> 0 | L40: Grupo 0 | N40: =IF(I40<H40,0,1) -> 1 | O40: =IFS(L40="Grupo 0",0,L40="Grupo 1",J40*D42,L40="Grupo 2",J40*D43,L40="Grupo 3",J40*D44,L40="Grupo 4",J40*D45,L40="Grupo 5",J40*D46) -> 0
...

Sheet FII
B1: Fundos | C1: Setor | D1: Quantidade | E1: Cotação | F1: Saldo | G1: %Carteira | H1: % Ideal | I1: Bal | J1: Bal | K1: Aporte: | L1: ='Distruibuição de aporte'!H6 -> 0 | M1: Vou aportar? | N1: Aporte ideal por ativo | O1: Quantidade | Q1: Valores total | R1: Ultimos prov. | S1: Somat prov.
A2: 1 | B2: BTLG11 | C2: Logistica | D2: 93 | E2: =IFERROR(__xludf.DUMMYFUNCTION("GOOGLEFINANCE(B2)"),103.8) -> 103.8 | F2: =D2*E2 -> 9653.4 | G2: =F2/F23 -> 0.060613032 | H2: =K2/K23 -> 0.18181818 | I2: =J2/J23 -> 0.12491586 | J2: =IF(L2=1,E24*H2-F2,0) -> 19303.469 | K2: =IF(Balanceamentos!C1>=0,Balanceamentos!C15,0) -> -2 | L2: =IFS(M2="Não",0,F2/E24<H2,1,F2/E24>H2,0) -> 1 | M2: Sim | N2: =I2*L1 -> 0 | O2: =IF(N2>0,N2/E2,0) -> 0 | Q2: =IF(O2=0, "" , E2*INT(O2)) | R2: 0.78 | S2: =IF(O2=0, "" , R2*INT(O2))
A3: 2 | B3: XPLG11 | C3: Logistica | D3: 94 | E3: =IFERROR(__xludf.DUMMYFUNCTION("GOOGLEFINANCE(B3)"),101.66) -> 101.66 | F3: =D3*E3 -> 9556.04 | G3: =F3/F23 -> 0.060001715 | H3: =K3/K23 -> 0.90909091 | I3: =J3/J23 -> 0.87508414 | J3: =IF(L3=1,E24*H3-F3,0) -> 135228.31 | K3: =Balanceamentos!D15 -> -10 | L3: =IFS(M3="Não",0,F3/E24<H3,1,F3/E24>H3,0) -> 1 | M3: Sim | N3: =I3*L1 -> 0 | O3: =IF(N3>0,N3/E3,0) -> 0 | Q3: =IF(O3=0, "" , E3*INT(O3)) | R3: 0.82 | S3: =IF(O3=0, "" , R3*INT(O3))
A4: 3 | B4: HGLG11 | C4: Logistica | D4: 59 | E4: =IFERROR(__xludf.DUMMYFUNCTION("GOOGLEFINANCE(B4)"),155.6) -> 155.6 | F4: =D4*E4 -> 9180.4 | G4: =F4/F23 -> 0.057643098 | H4: =K4/K23 -> -0.090909091 | I4: =J4/J23 -> 0 | J4: =IF(L4=1,E24*H4-F4,0) -> 0 | K4: =Balanceamentos!E15 -> 1 | L4: =IFS(M4="Não",0,F4/E24<H4,1,F4/E24>H4,0) -> 0 | M4: Sim | N4: =I4*L1 -> 0 | O4: =IF(N4>0,N4/E4,0) -> 0 | Q4: =IF(O4=0, "" , E4*INT(O4)) | R4: 1.1 | S4: =IF(O4=0, "" , R4*INT(O4))
A5: 4 | B5: GARE11 | C5: Logistica | D5: 1057 | E5: =IFERROR(__xludf.DUMMYFUNCTION("GOOGLEFINANCE(B5)"),8.36) -> 8.36 | F5: =D5*E5 -> 8836.52 | G5: =F5/F23 -> 0.055483899 | H5: =K5/K23 -> 0 | I5: =J5/J23 -> 0 | J5: =IF(L5=1,E24*H5-F5,0) -> 0 | K5: =Balanceamentos!F15 -> 0 | L5: =IFS(M5="Não",0,F5/E24<H5,1,F5/E24>H5,0) -> 0 | M5: Sim | N5: =I5*L1 -> 0 | O5: =IF(N5>0,N5/E5,0) -> 0 | Q5: =IF(O5=0, "" , E5*INT(O5)) | R5: 0.083 | S5: =IF(O5=0, "" , R5*INT(O5))
A6: 5 | B6: GGRC11 | C6: Logistica | D6: 909 | E6: =IFERROR(__xludf.DUMMYFUNCTION("GOOGLEFINANCE(B6)"),10.18) -> 10.18 | F6: =D6*E6 -> 9253.62 | G6: =F6/F23 -> 0.058102841 | H6: =K6/K23 -> 0 | I6: =J6/J23 -> 0 | J6: =IF(L6=1,E24*H6-F6,0) -> 0 | K6: =Balanceamentos!G15 -> 0 | L6: =IFS(M6="Não",0,F6/E24<H6,1,F6/E24>H6,0) -> 0 | M6: Sim | N6: =I6*L1 -> 0 | O6: =IF(N6>0,N6/E6,0) -> 0 | Q6: =IF(O6=0, "" , E6*INT(O6)) | R6: 0.1 | S6: =IF(O6=0, "" , R6*INT(O6))
A7: 6 | B7: HGBS11 | C7: Shopping | D7: 460 | E7: =IFERROR(__xludf.DUMMYFUNCTION("GOOGLEFINANCE(B7)"),20.23) -> 20.23 | F7: =D7*E7 -> 9305.8 | G7: =F7/F23 -> 0.058430476 | H7: =K7/K23 -> 0 | I7: =J7/J23 -> 0 | J7: =IF(L7=1,E24*H7-F7,0) -> 0 | K7: =Balanceamentos!H15 -> 0 | L7: =IFS(M7="Não",0,F7/E24<H7,1,F7/E24>H7,0) -> 0 | M7: Sim | N7: =I7*L1 -> 0 | O7: =IF(N7>0,N7/E7,0) -> 0 | Q7: =IF(O7=0, "" , E7*INT(O7)) | R7: 1.6 | S7: =IF(O7=0, "" , R7*INT(O7))
A8: 7 | B8: HSML11 | C8: Shopping | D8: 109 | E8: =IFERROR(__xludf.DUMMYFUNCTION("GOOGLEFINANCE(B8)"),95.0) -> 95 | F8: =D8*E8 -> 10355 | G8: =F8/F23 -> 0.06501833 | H8: =K8/K23 -> 0 | I8: =J8/J23 -> 0 | J8: =IF(L8=1,E24*H8-F8,0) -> 0 | K8: =Balanceamentos!I15 -> 0 | L8: =IFS(M8="Não",0,F8/E24<H8,1,F8/E24>H8,0) -> 0 | M8: Sim | N8: =I8*L1 -> 0 | O8: =IF(N8>0,N8/E8,0) -> 0 | Q8: =IF(O8=0, "" , E8*INT(O8)) | R8: 0.65 | S8: =IF(O8=0, "" , R8*INT(O8))
A9: 8 | B9: HGRU11 | C9: Varejo | D9: 76 | E9: =IFERROR(__xludf.DUMMYFUNCTION("GOOGLEFINANCE(B9)"),129.27) -> 129.27 | F9: =D9*E9 -> 9824.52 | G9: =F9/F23 -> 0.061687483 | H9: =K9/K23 -> 0 | I9: =J9/J23 -> 0 | J9: =IF(L9=1,E24*H9-F9,0) -> 0 | K9: =Balanceamentos!J15 -> 0 | L9: =IFS(M9="Não",0,F9/E24<H9,1,F9/E24>H9,0) -> 0 | M9: Sim | N9: =I9*L1 -> 0 | O9: =IF(N9>0,N9/E9,0) -> 0 | Q9: =IF(O9=0, "" , E9*INT(O9)) | R9: 0.9 | S9: =IF(O9=0, "" , R9*INT(O9))
A10: 9 | B10: SEQR11 | C10: Varejo | D10: 186 | E10: =IFERROR(__xludf.DUMMYFUNCTION("GOOGLEFINANCE(B10)"),55.69) -> 55.69 | F10: =D10*E10 -> 10358.34 | G10: =F10/F23 -> 0.065039302 | H10: =K10/K23 -> 0 | I10: =J10/J23 -> 0 | J10: =IF(L10=1,E24*H10-F10,0) -> 0 | K10: =Balanceamentos!K15 -> 0 | L10: =IFS(M10="Não",0,F10/E24<H10,1,F10/E24>H10,0) -> 0 | M10: Sim | N10: =I10*L1 -> 0 | O10: =IF(N10>0,N10/E10,0) -> 0 | Q10: =IF(O10=0, "" , E10*INT(O10)) | R10: 0.5823 | S10: =IF(O10=0, "" , R10*INT(O10))
A11: 10 | B11: TRXF11 | C11: Varejo | D11: 90 | E11: =IFERROR(__xludf.DUMMYFUNCTION("GOOGLEFINANCE(B11)"),91.76) -> 91.76 | F11: =D11*E11 -> 8258.4 | G11: =F11/F23 -> 0.051853923 | H11: =K11/K23 -> 0 | I11: =J11/J23 -> 0 | J11: =IF(L11=1,E24*H11-F11,0) -> 0 | K11: =Balanceamentos!L15 -> 0 | L11: =IFS(M11="Não",0,F11/E24<H11,1,F11/E24>H11,0) -> 0 | M11: Sim | N11: =I11*L1 -> 0 | O11: =IF(N11>0,N11/E11,0) -> 0 | Q11: =IF(O11=0, "" , E11*INT(O11)) | R11: 0.93 | S11: =IF(O11=0, "" , R11*INT(O11))
A12: 11 | B12: RZAT11 | C12: Varejo | D12: 120 | E12: =IFERROR(__xludf.DUMMYFUNCTION("GOOGLEFINANCE(B12)"),90.06) -> 90.06 | F12: =D12*E12 -> 10807.2 | G12: =F12/F23 -> 0.067857663 | H12: =K12/K23 -> 0 | I12: =J12/J23 -> 0 | J12: =IF(L12=1,E24*H12-F12,0) -> 0 | K12: =Balanceamentos!M15 -> 0 | L12: =IFS(M12="Não",0,F12/E24<H12,1,F12/E24>H12,0) -> 0 | M12: Sim | N12: =I12*L1 -> 0 | O12: =IF(N12>0,N12/E12,0) -> 0 | Q12: =IF(O12=0, "" , E12*INT(O12)) | R12: 1.1 | S12: =IF(O12=0, "" , R12*INT(O12))
A13: 12 | B13: KNCR11 | C13: Papel | D13: 10 | E13: =IFERROR(__xludf.DUMMYFUNCTION("GOOGLEFINANCE(B13)"),105.03) -> 105.03 | F13: =D13*E13 -> 1050.3 | G13: =F13/F23 -> 0.0065947612 | H13: =K13/K23 -> 0 | I13: =J13/J23 -> 0 | J13: =IF(L13=1,E24*H13-F13,0) -> 0 | K13: =Balanceamentos!N15 -> 0 | L13: =IFS(M13="Não",0,F13/E24<H13,1,F13/E24>H13,0) -> 0 | M13: Sim | N13: =I13*L1 -> 0 | O13: =IF(N13>0,N13/E13,0) -> 0 | Q13: =IF(O13=0, "" , E13*INT(O13)) | R13: 0.95 | S13: =IF(O13=0, "" , R13*INT(O13))
A14: 13 | B14: KNSC11 | C14: Papel | D14: 224 | E14: =IFERROR(__xludf.DUMMYFUNCTION("GOOGLEFINANCE(B14)"),8.88) -> 8.88 | F14: =D14*E14 -> 1989.12 | G14: =F14/F23 -> 0.012489547 | H14: =K14/K23 -> 0 | I14: =J14/J23 -> 0 | J14: =IF(L14=1,E24*H14-F14,0) -> 0 | K14: =Balanceamentos!O15 -> 0 | L14: =IFS(M14="Não",0,F14/E24<H14,1,F14/E24>H14,0) -> 0 | M14: Sim | N14: =I14*L1 -> 0 | O14: =IF(N14>0,N14/E14,0) -> 0 | Q14: =IF(O14=0, "" , E14*INT(O14)) | R14: 0.08 | S14: =IF(O14=0, "" , R14*INT(O14))
A15: 14 | B15: MXRF11 | C15: Papel | D15: 305 | E15: =IFERROR(__xludf.DUMMYFUNCTION("GOOGLEFINANCE(B15)"),9.72) -> 9.72 | F15: =D15*E15 -> 2964.6 | G15: =F15/F23 -> 0.018614519 | H15: =K15/K23 -> 0 | I15: =J15/J23 -> 0 | J15: =IF(L15=1,E24*H15-F15,0) -> 0 | K15: =Balanceamentos!P15 -> 0 | L15: =IFS(M15="Não",0,F15/E24<H15,1,F15/E24>H15,0) -> 0 | M15: Sim | N15: =I15*L1 -> 0 | O15: =IF(N15>0,N15/E15,0) -> 0 | Q15: =IF(O15=0, "" , E15*INT(O15)) | R15: 0.1 | S15: =IF(O15=0, "" , R15*INT(O15))
A16: 15 | B16: PCIP11 | C16: Papel | D16: 62 | E16: =IFERROR(__xludf.DUMMYFUNCTION("GOOGLEFINANCE(""BVMF:PCIP11"")"),85.5) -> 85.5 | F16: =D16*E16 -> 5301 | G16: =F16/F23 -> 0.033284613 | H16: =K16/K23 -> 0 | I16: =J16/J23 -> 0 | J16: =IF(L16=1,E24*H16-F16,0) -> 0 | K16: =Balanceamentos!Q15 -> 0 | L16: =IFS(M16="Não",0,F16/E24<H16,1,F16/E24>H16,0) -> 0 | M16: Sim | N16: =I16*L1 -> 0 | O16: =IF(N16>0,N16/E16,0) -> 0 | Q16: =IF(O16=0, "" , E16*INT(O16)) | R16: 0.9 | S16: =IF(O16=0, "" , R16*INT(O16))
A17: 16 | B17: CPTI11 | C17: Infra | D17: 105 | E17: =IFERROR(__xludf.DUMMYFUNCTION("GOOGLEFINANCE(""BVMF:CPTI11"")"),89.45) -> 89.45 | F17: =D17*E17 -> 9392.25 | G17: =F17/F23 -> 0.058973289 | H17: =K17/K23 -> 0 | I17: =J17/J23 -> 0 | J17: =IF(L17=1,E24*H17-F17,0) -> 0 | K17: =Balanceamentos!R15 -> 0 | L17: =IFS(M17="Não",0,F17/E24<H17,1,F17/E24>H17,0) -> 0 | M17: Sim | N17: =I17*L1 -> 0 | O17: =IF(N17>0,N17/E17,0) -> 0 | Q17: =IF(O17=0, "" , E17*INT(O17)) | R17: 1 | S17: =IF(O17=0, "" , R17*INT(O17))
A18: 17 | B18: JURO11 | C18: Infra | D18: 93 | E18: =IFERROR(__xludf.DUMMYFUNCTION("GOOGLEFINANCE(B18)"),102.99) -> 102.99 | F18: =D18*E18 -> 9578.07 | G18: =F18/F23 -> 0.06014004 | H18: =K18/K23 -> 0 | I18: =J18/J23 -> 0 | J18: =IF(L18=1,E24*H18-F18,0) -> 0 | K18: =Balanceamentos!S15 -> 0 | L18: =IFS(M18="Não",0,F18/E24<H18,1,F18/E24>H18,0) -> 0 | M18: Sim | N18: =I18*L1 -> 0 | O18: =IF(N18>0,N18/E18,0) -> 0 | Q18: =IF(O18=0, "" , E18*INT(O18)) | R18: 1 | S18: =IF(O18=0, "" , R18*INT(O18))
A19: 18 | B19: RZTR11 | C19: Agro | D19: 101 | E19: =IFERROR(__xludf.DUMMYFUNCTION("GOOGLEFINANCE(""BVMF:RZTR11"")"),95.26) -> 95.26 | F19: =D19*E19 -> 9621.26 | G19: =F19/F23 -> 0.060411227 | H19: =K19/K23 -> 0 | I19: =J19/J23 -> 0 | J19: =IF(L19=1,E24*H19-F19,0) -> 0 | K19: =Balanceamentos!T15 -> 0 | L19: =IFS(M19="Não",0,F19/E24<H19,1,F19/E24>H19,0) -> 0 | M19: Sim | N19: =I19*L1 -> 0 | O19: =IF(N19>0,N19/E19,0) -> 0 | Q19: =IF(O19=0, "" , E19*INT(O19)) | R19: 1.05 | S19: =IF(O19=0, "" , R19*INT(O19))
A20: 19 | B20: SNAG11 | C20: Fiagro | D20: 518 | E20: =IFERROR(__xludf.DUMMYFUNCTION("GOOGLEFINANCE(B20)"),10.68) -> 10.68 | F20: =D20*E20 -> 5532.24 | G20: =F20/F23 -> 0.034736553 | H20: =K20/K23 -> 0 | I20: =J20/J23 -> 0 | J20: =IF(L20=1,E24*H20-F20,0) -> 0 | K20: =Balanceamentos!U15 -> 0 | L20: =IFS(M20="Não",0,F20/E24<H20,1,F20/E24>H20,0) -> 0 | M20: Sim | N20: =I20*L1 -> 0 | O20: =IF(N20>0,N20/E20,0) -> 0 | Q20: =IF(O20=0, "" , E20*INT(O20)) | R20: 0.1 | S20: =IF(O20=0, "" , R20*INT(O20))
A21: 20 | B21: SNEL11 | C21: Energia | D21: 990 | E21: =IFERROR(__xludf.DUMMYFUNCTION("GOOGLEFINANCE(B21)"),8.53) -> 8.53 | F21: =D21*E21 -> 8444.7 | G21: =F21/F23 -> 0.053023688 | H21: =K21/K23 -> 0 | I21: =J21/J23 -> 0 | J21: =IF(L21=1,E24*H21-F21,0) -> 0 | K21: =Balanceamentos!V15 -> 0 | L21: =IFS(M21="Não",0,F21/E24<H21,1,F21/E24>H21,0) -> 0 | M21: Sim | N21: =I21*L1 -> 0 | O21: =IF(N21>0,N21/E21,0) -> 0 | Q21: =IF(O21=0, "" , E21*INT(O21)) | R21: 0.1 | S21: =IF(O21=0, "" , R21*INT(O21))
A22: 21 | I22: =J22/J23 -> 0 | J22: =IF(L22=1,E24*H22-F22,0) -> 0 | K22: =Balanceamentos!W15 -> 0 | L22: =IFS(M22="Não",0,F22/E24<H22,1,F22/E24>H22,0) -> 0 | M22: Não | N22: =I22*L1 -> 0 | O22: =IF(N22>0,N22/E22,0) -> 0 | Q22: =IF(O22=0, "" , E22*INT(O22)) | S22: =IF(O22=0, "" , R22*INT(O22))
B23: TOTAL | E23: =SUM(E2:E22) -> 1377.65 | F23: =SUM(F2:F22) -> 159262.78 | G23: =SUM(G2:G22) -> 1 | H23: =SUM(H2:H22) -> 1 | I23: =SUM(I2:I22) -> 1 | J23: =SUM(J2:J22) -> 154531.77 | K23: =SUM(K2:K22) -> -11 | L23: A aportar: | M23: =COUNTIF(M2:M22,"SIM") -> 20 | N23: =SUM(N2:N22) -> 0 | P23: Soma | Q23: =SUM(Q2:Q22) -> 0 | S23: =SUM(S2:S22) -> 0
D24: =L1+F24 -> 19209.44 | E24: =L1+F23 -> 159262.78 | F24: =SUMIFS(F2:F22,L2:L22,1) -> 19209.44 | K24: =SUMIF(L2:L22,1,K2:K22) -> -12 | S24: =S23/Q23 -> #DIV/0!

Sheet Ações
B1: Ação | C1: Quantidade | D1: Cotação | E1: Saldo | F1: %Carteira | G1: % Ideal | H1: Bal | I1: Bal | K1: Aporte: | L1: ='Distruibuição de aporte'!H7 -> 4428.5082 | M1: Aporte ideal por ativo | N1: Quantidade
A2: 1 | B2: VALE3 | C2: 54 | D2: =IFERROR(__xludf.DUMMYFUNCTION("GOOGLEFINANCE(""BVMF:VALE3"")"),77.13) -> 77.13 | E2: =C2*D2 -> 4165.02 | F2: =E2/E102 -> 0.10289023 | G2: =IFS(J2="Grupo 0",0,J2="Grupo 1",K2*H105/100,J2="Grupo 2",K2*I105/100,J2="Grupo 3",K2*J105/100,J2="Grupo 4",K2*K105/100) -> 0.031428571 | H2: =IF(L2=1,I2/I102,0) -> 0 | I2: =IF(L2=1,C102*G2-E2,0) -> 0 | J2: Grupo 1 | K2: =IF(Balanceamentos!C37>0,Balanceamentos!C37,0) -> 11 | L2: =IF(G2>E2/C102,1,0) -> 0 | M2: =IF(L2=1,H2*L1,0) -> 0 | N2: =IF(M2>0,M2/D2,0) -> 0
A3: 2 | B3: BBAS3 | C3: 73 | D3: =IFERROR(__xludf.DUMMYFUNCTION("GOOGLEFINANCE(""BVMF:BBAS3"")"),23.41) -> 23.41 | E3: =C3*D3 -> 1708.93 | F3: =E3/E102 -> 0.04221641 | G3: =IFS(J3="Grupo 0",0,J3="Grupo 1",K3*H105/100,J3="Grupo 2",K3*I105/100,J3="Grupo 3",K3*J105/100,J3="Grupo 4",K3*K105/100) -> 0.031428571 | H3: =IF(L3=1,I3/I102,0) -> 0 | I3: =IF(L3=1,C102*G3-E3,0) -> 0 | J3: Grupo 1 | K3: =IF(Balanceamentos!D37>0,Balanceamentos!D37,0) -> 11 | L3: =IF(G3>E3/C102,1,0) -> 0 | M3: =IF(L3=1,H3*L1,0) -> 0 | N3: =IF(M3>0,M3/D3,0) -> 0
A4: 3 | B4: PETR4 | C4: 37 | D4: =IFERROR(__xludf.DUMMYFUNCTION("GOOGLEFINANCE(B4)"),47.0) -> 47 | E4: =C4*D4 -> 1739 | F4: =E4/E102 -> 0.042959242 | G4: =IFS(J4="Grupo 0",0,J4="Grupo 1",K4*H105/100,J4="Grupo 2",K4*I105/100,J4="Grupo 3",K4*J105/100,J4="Grupo 4",K4*K105/100) -> 0.025714286 | H4: =IF(L4=1,I4/I102,0) -> 0 | I4: =IF(L4=1,C102*G4-E4,0) -> 0 | J4: Grupo 1 | K4: =IF(Balanceamentos!E37>0,Balanceamentos!E37,0) -> 9 | L4: =IF(G4>E4/C102,1,0) -> 0 | M4: =IF(L4=1,H4*L1,0) -> 0 | N4: =IF(M4>0,M4/D4,0) -> 0
A5: 4 | B5: CSMG3 | C5: 11 | D5: =IFERROR(__xludf.DUMMYFUNCTION("GOOGLEFINANCE(B5)"),54.2) -> 54.2 | E5: =C5*D5 -> 596.2 | F5: =E5/E102 -> 0.014728177 | G5: =IFS(J5="Grupo 0",0,J5="Grupo 1",K5*H105/100,J5="Grupo 2",K5*I105/100,J5="Grupo 3",K5*J105/100,J5="Grupo 4",K5*K105/100) -> 0.006 | H5: =IF(L5=1,I5/I102,0) -> 0 | I5: =IF(L5=1,C102*G5-E5,0) -> 0 | J5: Grupo 3 | K5: =IF(Balanceamentos!F37>0,Balanceamentos!F37,0) -> 5 | L5: =IF(G5>E5/C102,1,0) -> 0 | M5: =IF(L5=1,H5*L1,0) -> 0 | N5: =IF(M5>0,M5/D5,0) -> 0
A6: 5 | B6: CMIG4 | C6: 21 | D6: =IFERROR(__xludf.DUMMYFUNCTION("GOOGLEFINANCE(B6)"),11.81) -> 11.81 | E6: =C6*D6 -> 248.01 | F6: =E6/E102 -> 0.0061266944 | G6: =IFS(J6="Grupo 0",0,J6="Grupo 1",K6*H105/100,J6="Grupo 2",K6*I105/100,J6="Grupo 3",K6*J105/100,J6="Grupo 4",K6*K105/100) -> 0 | H6: =IF(L6=1,I6/I102,0) -> 0 | I6: =IF(L6=1,C102*G6-E6,0) -> 0 | J6: Grupo 0 | K6: 0 | L6: =IF(G6>E6/C102,1,0) -> 0 | M6: =IF(L6=1,H6*L1,0) -> 0 | N6: =IF(M6>0,M6/D6,0) -> 0
A7: 6 | B7: ITSA4 | C7: 7 | D7: =IFERROR(__xludf.DUMMYFUNCTION("GOOGLEFINANCE(B7)"),13.37) -> 13.37 | E7: =C7*D7 -> 93.59 | F7: =E7/E102 -> 0.0023119928 | G7: =IFS(J7="Grupo 0",0,J7="Grupo 1",K7*H105/100,J7="Grupo 2",K7*I105/100,J7="Grupo 3",K7*J105/100,J7="Grupo 4",K7*K105/100) -> 0 | H7: =IF(L7=1,I7/I102,0) -> 0 | I7: =IF(L7=1,C102*G7-E7,0) -> 0 | J7: Grupo 0 | K7: 0 | L7: =IF(G7>E7/C102,1,0) -> 0 | M7: =IF(L7=1,H7*L1,0) -> 0 | N7: =IF(M7>0,M7/D7,0) -> 0
A8: 7 | B8: ISAE3 | C8: 14 | D8: =IFERROR(__xludf.DUMMYFUNCTION("GOOGLEFINANCE(B8)"),32.61) -> 32.61 | E8: =C8*D8 -> 456.54 | F8: =E8/E102 -> 0.011278098 | G8: =IFS(J8="Grupo 0",0,J8="Grupo 1",K8*H105/100,J8="Grupo 2",K8*I105/100,J8="Grupo 3",K8*J105/100,J8="Grupo 4",K8*K105/100) -> 0.012162162 | H8: =IF(L8=1,I8/I102,0) -> 0.0097973736 | I8: =IF(L8=1,C102*G8-E8,0) -> 89.647356 | J8: Grupo 2 | K8: =IF(Balanceamentos!G37>0,Balanceamentos!G37,0) -> 9 | L8: =IF(G8>E8/C102,1,0) -> 1 | M8: =IF(L8=1,H8*L1,0) -> 43.387749 | N8: =IF(M8>0,M8/D8,0) -> 1.3305044
A9: 8 | B9: UNIP6 | C9: 1 | D9: =IFERROR(__xludf.DUMMYFUNCTION("GOOGLEFINANCE(B9)"),63.15) -> 63.15 | E9: =C9*D9 -> 63.15 | F9: =E9/E102 -> 0.0015600208 | G9: =IFS(J9="Grupo 0",0,J9="Grupo 1",K9*H105/100,J9="Grupo 2",K9*I105/100,J9="Grupo 3",K9*J105/100,J9="Grupo 4",K9*K105/100) -> 0 | H9: =IF(L9=1,I9/I102,0) -> 0 | I9: =IF(L9=1,C102*G9-E9,0) -> 0 | J9: Grupo 0 | K9: 0 | L9: =IF(G9>E9/C102,1,0) -> 0 | M9: =IF(L9=1,H9*L1,0) -> 0 | N9: =IF(M9>0,M9/D9,0) -> 0
A10: 9 | B10: BBSE3 | C10: 31 | D10: =IFERROR(__xludf.DUMMYFUNCTION("GOOGLEFINANCE(B10)"),34.52) -> 34.52 | E10: =C10*D10 -> 1070.12 | F10: =E10/E102 -> 0.026435621 | G10: =IFS(J10="Grupo 0",0,J10="Grupo 1",K10*H105/100,J10="Grupo 2",K10*I105/100,J10="Grupo 3",K10*J105/100,J10="Grupo 4",K10*K105/100) -> 0.031428571 | H10: =IF(L10=1,I10/I102,0) -> 0.037299694 | I10: =IF(L10=1,C102*G10-E10,0) -> 341.29748 | J10: Grupo 1 | K10: =IF(Balanceamentos!H37>0,Balanceamentos!H37,0) -> 11 | L10: =IF(G10>E10/C102,1,0) -> 1 | M10: =IF(L10=1,H10*L1,0) -> 165.182 | N10: =IF(M10>0,M10/D10,0) -> 4.7851101
A11: 10 | B11: TAEE11 | C11: 1 | D11: =IFERROR(__xludf.DUMMYFUNCTION("GOOGLEFINANCE(B11)"),41.85) -> 41.85 | E11: =C11*D11 -> 41.85 | F11: =E11/E102 -> 0.001033838 | G11: =IFS(J11="Grupo 0",0,J11="Grupo 1",K11*H105/100,J11="Grupo 2",K11*I105/100,J11="Grupo 3",K11*J105/100,J11="Grupo 4",K11*K105/100) -> 0 | H11: =IF(L11=1,I11/I102,0) -> 0 | I11: =IF(L11=1,C102*G11-E11,0) -> 0 | J11: Grupo 0 | K11: 0 | L11: =IF(G11>E11/C102,1,0) -> 0 | M11: =IF(L11=1,H11*L1,0) -> 0 | N11: =IF(M11>0,M11/D11,0) -> 0
A12: 11 | B12: ABCB4 | C12: 15 | D12: =IFERROR(__xludf.DUMMYFUNCTION("GOOGLEFINANCE(B12)"),25.82) -> 25.82 | E12: =C12*D12 -> 387.3 | F12: =E12/E102 -> 0.0095676334 | G12: =IFS(J12="Grupo 0",0,J12="Grupo 1",K12*H105/100,J12="Grupo 2",K12*I105/100,J12="Grupo 3",K12*J105/100,J12="Grupo 4",K12*K105/100) -> 0.0094594595 | H12: =IF(L12=1,I12/I102,0) -> 0.0040996511 | I12: =IF(L12=1,C102*G12-E12,0) -> 37.512388 | J12: Grupo 2 | K12: =IF(Balanceamentos!I37>0,Balanceamentos!I37,0) -> 7 | L12: =IF(G12>E12/C102,1,0) -> 1 | M12: =IF(L12=1,H12*L1,0) -> 18.155338 | N12: =IF(M12>0,M12/D12,0) -> 0.7031502
